Workbook

Sheet Start
B2: StratOS Workbook
B3: Strategy analysis worksheets
B4: Blank template.
B6: How to use | C6: Each sheet is one StratOS framework. Type only in the cream cells (blue text). Grey cells are formulas: they score, rank and flag automatically. Every finding should name its evidence in the Source column, the same rule StratOS follows.
B7: Colour key | C7: Blue on cream = input · black on grey = formula · green / amber / red = status.
B8: PESTEL | C8: Macro findings with impact × certainty priority and the P&L line each one hits.
B9: Five Forces | C9: Sub-factor scores roll up to each force and to an industry attractiveness score.
B10: KSF Scorecard | C10: Weighted KSFs, every competitor scored, totals and rank; weights must sum to 100%.
B11: VRIO | C11: Yes / No / ? for each test; the verdict and the KSF reality check are calculated.
B12: SWOT-TOWS | C12: Four traced lists and the TOWS options that pair them.
B13: Decision Matrix | C13: Criteria weights × option scores, with a weighted total and rank; do nothing included.
B14: Expected Value | C14: Scenario probabilities × NPVs, expected NPV, worst case, maximin, value of information, and a Bayes' rule pilot check (EVSI).
B15: Business Case | C15: Driver-based cash flows, NPV, IRR and cumulative cash.
B16: Risk Analysis | C16: Exhibit Q-3: a tornado chart (which driver moves NPV most) and a 1,000-run Monte Carlo simulation (median, P10-P90, chance NPV is below zero) over your low / likely / high ranges.
B17: Balanced Scorecard | C17: Objectives and measures in four perspectives, leading vs lagging, status vs target, balance check.
... B23: Your work stays yours | C23: In graded work, the inputs, choices and every Impact Summary are the student's. The workbook calculates; it never decides.
B25: © 2026 Brad Scheller · StratOS Strategy Lab · Apache-2.0

Sheet PESTEL
A1: PESTEL Analysis
A2: Macro findings, each tied to a P&L line. Priority = impact × certainty (1-25).
A3: Blue text on cream = your inputs. Black on grey = formulas (do not type over them).
A5: ID | B5: Dimension | C5: Finding | D5: Direction (+ / - / ±) | E5: Impact 1-5 | F5: Certainty 1-5 | G5: Priority | H5: P&L line | I5: Source / evidence
G6: =IF(AND(ISNUMBER(E6),ISNUMBER(F6)),E6*F6,"")
G7: =IF(AND(ISNUMBER(E7),ISNUMBER(F7)),E7*F7,"")
G8: =IF(AND(ISNUMBER(E8),ISNUMBER(F8)),E8*F8,"")
G9: =IF(AND(ISNUMBER(E9),ISNUMBER(F9)),E9*F9,"")
G10: =IF(AND(ISNUMBER(E10),ISNUMBER(F10)),E10*F10,"")
G11: =IF(AND(ISNUMBER(E11),ISNUMBER(F11)),E11*F11,"")
G12: =IF(AND(ISNUMBER(E12),ISNUMBER(F12)),E12*F12,"")
G13: =IF(AND(ISNUMBER(E13),ISNUMBER(F13)),E13*F13,"")
G14: =IF(AND(ISNUMBER(E14),ISNUMBER(F14)),E14*F14,"")
G15: =IF(AND(ISNUMBER(E15),ISNUMBER(F15)),E15*F15,"")
G16: =IF(AND(ISNUMBER(E16),ISNUMBER(F16)),E16*F16,"")
G17: =IF(AND(ISNUMBER(E17),ISNUMBER(F17)),E17*F17,"")
... G30: =IF(AND(ISNUMBER(E30),ISNUMBER(F30)),E30*F30,"")
B32: Findings | C32: =COUNTA(C6:C30) -> 0
B33: High priority (≥16) | C33: =COUNTIF(G6:G30,">=16") -> 0
B34: Missing a source | C34: =SUMPRODUCT((C6:C30<>"")*(I6:I30="")) -> 0

Sheet Five Forces
A1: Porter's Five Forces
A2: Score each sub-factor 1 (weak force, good for profit) to 5 (strong force). A force score you enter overrides the sub-factor average.
A3: Blue text on cream = your inputs. Black on grey = formulas (do not type over them).
A5: Force | B5: Sub-factor | C5: Score 1-5 | D5: Evidence / source
A6: Competitive rivalry | B6: Current competition
A7: Competitive rivalry | B7: Market growth
A8: Competitive rivalry | B8: Exit barriers
A9: Competitive rivalry | B9: Differentiation
A10: Supplier power | B10: Supplier concentration
A11: Supplier power | B11: Switching costs
A12: Supplier power | B12: Forward integration
A13: Supplier power | B13: Input uniqueness
A14: Buyer power | B14: Buyer concentration
A15: Buyer power | B15: Purchase volume
A16: Buyer power | B16: Switching costs
A17: Buyer power | B17: Price sensitivity
... A25: Threat of substitutes | B25: Buyer propensity
A27: Force | B27: Sub-factor average | C27: Your force score (optional) | D27: Score used | E27: Strength | F27: Horizon score (optional)
A28: Competitive rivalry | B28: =IFERROR(AVERAGEIF($A$6:$A$25,A28,$C$6:$C$25),"") | D28: =IF(ISNUMBER(C28),C28,B28) | E28: =IF(D28="","",IF(D28>=4,"Strong",IF(D28>=2.5,"Moderate","Weak")))
A29: Supplier power | B29: =IFERROR(AVERAGEIF($A$6:$A$25,A29,$C$6:$C$25),"") | D29: =IF(ISNUMBER(C29),C29,B29) | E29: =IF(D29="","",IF(D29>=4,"Strong",IF(D29>=2.5,"Moderate","Weak")))
A30: Buyer power | B30: =IFERROR(AVERAGEIF($A$6:$A$25,A30,$C$6:$C$25),"") | D30: =IF(ISNUMBER(C30),C30,B30) | E30: =IF(D30="","",IF(D30>=4,"Strong",IF(D30>=2.5,"Moderate","Weak")))
A31: Threat of new entrants | B31: =IFERROR(AVERAGEIF($A$6:$A$25,A31,$C$6:$C$25),"") | D31: =IF(ISNUMBER(C31),C31,B31) | E31: =IF(D31="","",IF(D31>=4,"Strong",IF(D31>=2.5,"Moderate","Weak")))
A32: Threat of substitutes | B32: =IFERROR(AVERAGEIF($A$6:$A$25,A32,$C$6:$C$25),"") | D32: =IF(ISNUMBER(C32),C32,B32) | E32: =IF(D32="","",IF(D32>=4,"Strong",IF(D32>=2.5,"Moderate","Weak")))
A34: Industry attractiveness (1-5) | B34: =IFERROR(6-AVERAGE(D28:D32),"")
A35: At the horizon | B35: =IF(COUNT(F28:F32)=5,6-AVERAGE(F28:F32),"")
A37: Attractiveness = 6 minus the average force score (1-5; higher is more attractive).
A38: The horizon score appears once all five horizon scores are entered.

Sheet KSF Scorecard
A1: Key Success Factors Scorecard
A2: Weights are fractions that must sum to 100%. Score each competitor 1 (weak) to 5 (strong) on each KSF.
A3: Blue text on cream = your inputs. Black on grey = formulas (do not type over them).
A5: ID | B5: Key success factor | C5: Weight | D5: Traces to (force / driver) | E5: Competitor 1 | F5: Competitor 2 | G5: Competitor 3 | H5: Competitor 4 | I5: Competitor 5 | J5: Competitor 6
B16: Weight check (must be 100%) | C16: =SUM(C6:C15) -> 0 | D16: =IF(ABS(C16-1)<0.001,"OK","Weights must sum to 100%") -> Weights must sum to 100%
B17: Weighted score (out of 5) | E17: =IF(COUNT(E6:E15)=0,"",SUMPRODUCT($C$6:$C$15,E6:E15)) | F17: =IF(COUNT(F6:F15)=0,"",SUMPRODUCT($C$6:$C$15,F6:F15)) | G17: =IF(COUNT(G6:G15)=0,"",SUMPRODUCT($C$6:$C$15,G6:G15)) | H17: =IF(COUNT(H6:H15)=0,"",SUMPRODUCT($C$6:$C$15,H6:H15)) | I17: =IF(COUNT(I6:I15)=0,"",SUMPRODUCT($C$6:$C$15,I6:I15)) | J17: =IF(COUNT(J6:J15)=0,"",SUMPRODUCT($C$6:$C$15,J6:J15))
B18: Rank | E18: =IF(E17="","",RANK(E17,$E$17:$J$17)) | F18: =IF(F17="","",RANK(F17,$E$17:$J$17)) | G18: =IF(G17="","",RANK(G17,$E$17:$J$17)) | H18: =IF(H17="","",RANK(H17,$E$17:$J$17)) | I18: =IF(I17="","",RANK(I17,$E$17:$J$17)) | J18: =IF(J17="","",RANK(J17,$E$17:$J$17))

Sheet VRIO
A1: VRIO Analysis
A2: Answer the four tests in order with Yes / No / ?. The verdict stops at the first No or ?. KSF weight (a fraction) drives the reality check.
A3: Blue text on cream = your inputs. Black on grey = formulas (do not type over them).
A5: Resource or capability | B5: Type | C5: Valuable? | D5: Rare? | E5: Inimitable? | F5: Organized? | G5: Verdict | H5: KSF it delivers | I5: KSF weight | J5: Reality check | K5: Evidence
G6: =IF(A6="","",IF(C6<>"Yes",IF(C6="No","Competitive disadvantage","Undetermined"),IF(D6<>"Yes",IF(D6="No","Competitive parity","Undetermined beyond valuable"),IF(E6<>"Yes",IF(E6="No","Temporary advantage","Undetermined beyond rare"),IF(F6="Yes","Sustained advantage",IF(F6="No","Unexploited advantage","Undetermined beyond inimitable")))))) | J6: =IF(A6="","",IF(AND(C6="Yes",D6="Yes",E6="Yes",N(I6)<0.1),"Competence trap",IF(AND(OR(G6="Temporary advantage",G6="Unexploited advantage",G6="Sustained advantage"),N(I6)>=0.1),"Supported",IF(AND(G6="Competitive parity",N(I6)>=0.1),"Table stakes",""))))
G7: =IF(A7="","",IF(C7<>"Yes",IF(C7="No","Competitive disadvantage","Undetermined"),IF(D7<>"Yes",IF(D7="No","Competitive parity","Undetermined beyond valuable"),IF(E7<>"Yes",IF(E7="No","Temporary advantage","Undetermined beyond rare"),IF(F7="Yes","Sustained advantage",IF(F7="No","Unexploited advantage","Undetermined beyond inimitable")))))) | J7: =IF(A7="","",IF(AND(C7="Yes",D7="Yes",E7="Yes",N(I7)<0.1),"Competence trap",IF(AND(OR(G7="Temporary advantage",G7="Unexploited advantage",G7="Sustained advantage"),N(I7)>=0.1),"Supported",IF(AND(G7="Competitive parity",N(I7)>=0.1),"Table stakes",""))))
G8: =IF(A8="","",IF(C8<>"Yes",IF(C8="No","Competitive disadvantage","Undetermined"),IF(D8<>"Yes",IF(D8="No","Competitive parity","Undetermined beyond valuable"),IF(E8<>"Yes",IF(E8="No","Temporary advantage","Undetermined beyond rare"),IF(F8="Yes","Sustained advantage",IF(F8="No","Unexploited advantage","Undetermined beyond inimitable")))))) | J8: =IF(A8="","",IF(AND(C8="Yes",D8="Yes",E8="Yes",N(I8)<0.1),"Competence trap",IF(AND(OR(G8="Temporary advantage",G8="Unexploited advantage",G8="Sustained advantage"),N(I8)>=0.1),"Supported",IF(AND(G8="Competitive parity",N(I8)>=0.1),"Table stakes",""))))
G9: =IF(A9="","",IF(C9<>"Yes",IF(C9="No","Competitive disadvantage","Undetermined"),IF(D9<>"Yes",IF(D9="No","Competitive parity","Undetermined beyond valuable"),IF(E9<>"Yes",IF(E9="No","Temporary advantage","Undetermined beyond rare"),IF(F9="Yes","Sustained advantage",IF(F9="No","Unexploited advantage","Undetermined beyond inimitable")))))) | J9: =IF(A9="","",IF(AND(C9="Yes",D9="Yes",E9="Yes",N(I9)<0.1),"Competence trap",IF(AND(OR(G9="Temporary advantage",G9="Unexploited advantage",G9="Sustained advantage"),N(I9)>=0.1),"Supported",IF(AND(G9="Competitive parity",N(I9)>=0.1),"Table stakes",""))))
G10: =IF(A10="","",IF(C10<>"Yes",IF(C10="No","Competitive disadvantage","Undetermined"),IF(D10<>"Yes",IF(D10="No","Competitive parity","Undetermined beyond valuable"),IF(E10<>"Yes",IF(E10="No","Temporary advantage","Undetermined beyond rare"),IF(F10="Yes","Sustained advantage",IF(F10="No","Unexploited advantage","Undetermined beyond inimitable")))))) | J10: =IF(A10="","",IF(AND(C10="Yes",D10="Yes",E10="Yes",N(I10)<0.1),"Competence trap",IF(AND(OR(G10="Temporary advantage",G10="Unexploited advantage",G10="Sustained advantage"),N(I10)>=0.1),"Supported",IF(AND(G10="Competitive parity",N(I10)>=0.1),"Table stakes",""))))
G11: =IF(A11="","",IF(C11<>"Yes",IF(C11="No","Competitive disadvantage","Undetermined"),IF(D11<>"Yes",IF(D11="No","Competitive parity","Undetermined beyond valuable"),IF(E11<>"Yes",IF(E11="No","Temporary advantage","Undetermined beyond rare"),IF(F11="Yes","Sustained advantage",IF(F11="No","Unexploited advantage","Undetermined beyond inimitable")))))) | J11: =IF(A11="","",IF(AND(C11="Yes",D11="Yes",E11="Yes",N(I11)<0.1),"Competence trap",IF(AND(OR(G11="Temporary advantage",G11="Unexploited advantage",G11="Sustained advantage"),N(I11)>=0.1),"Supported",IF(AND(G11="Competitive parity",N(I11)>=0.1),"Table stakes",""))))
G12: =IF(A12="","",IF(C12<>"Yes",IF(C12="No","Competitive disadvantage","Undetermined"),IF(D12<>"Yes",IF(D12="No","Competitive parity","Undetermined beyond valuable"),IF(E12<>"Yes",IF(E12="No","Temporary advantage","Undetermined beyond rare"),IF(F12="Yes","Sustained advantage",IF(F12="No","Unexploited advantage","Undetermined beyond inimitable")))))) | J12: =IF(A12="","",IF(AND(C12="Yes",D12="Yes",E12="Yes",N(I12)<0.1),"Competence trap",IF(AND(OR(G12="Temporary advantage",G12="Unexploited advantage",G12="Sustained advantage"),N(I12)>=0.1),"Supported",IF(AND(G12="Competitive parity",N(I12)>=0.1),"Table stakes",""))))
G13: =IF(A13="","",IF(C13<>"Yes",IF(C13="No","Competitive disadvantage","Undetermined"),IF(D13<>"Yes",IF(D13="No","Competitive parity","Undetermined beyond valuable"),IF(E13<>"Yes",IF(E13="No","Temporary advantage","Undetermined beyond rare"),IF(F13="Yes","Sustained advantage",IF(F13="No","Unexploited advantage","Undetermined beyond inimitable")))))) | J13: =IF(A13="","",IF(AND(C13="Yes",D13="Yes",E13="Yes",N(I13)<0.1),"Competence trap",IF(AND(OR(G13="Temporary advantage",G13="Unexploited advantage",G13="Sustained advantage"),N(I13)>=0.1),"Supported",IF(AND(G13="Competitive parity",N(I13)>=0.1),"Table stakes",""))))
G14: =IF(A14="","",IF(C14<>"Yes",IF(C14="No","Competitive disadvantage","Undetermined"),IF(D14<>"Yes",IF(D14="No","Competitive parity","Undetermined beyond valuable"),IF(E14<>"Yes",IF(E14="No","Temporary advantage","Undetermined beyond rare"),IF(F14="Yes","Sustained advantage",IF(F14="No","Unexploited advantage","Undetermined beyond inimitable")))))) | J14: =IF(A14="","",IF(AND(C14="Yes",D14="Yes",E14="Yes",N(I14)<0.1),"Competence trap",IF(AND(OR(G14="Temporary advantage",G14="Unexploited advantage",G14="Sustained advantage"),N(I14)>=0.1),"Supported",IF(AND(G14="Competitive parity",N(I14)>=0.1),"Table stakes",""))))
G15: =IF(A15="","",IF(C15<>"Yes",IF(C15="No","Competitive disadvantage","Undetermined"),IF(D15<>"Yes",IF(D15="No","Competitive parity","Undetermined beyond valuable"),IF(E15<>"Yes",IF(E15="No","Temporary advantage","Undetermined beyond rare"),IF(F15="Yes","Sustained advantage",IF(F15="No","Unexploited advantage","Undetermined beyond inimitable")))))) | J15: =IF(A15="","",IF(AND(C15="Yes",D15="Yes",E15="Yes",N(I15)<0.1),"Competence trap",IF(AND(OR(G15="Temporary advantage",G15="Unexploited advantage",G15="Sustained advantage"),N(I15)>=0.1),"Supported",IF(AND(G15="Competitive parity",N(I15)>=0.1),"Table stakes",""))))
G16: =IF(A16="","",IF(C16<>"Yes",IF(C16="No","Competitive disadvantage","Undetermined"),IF(D16<>"Yes",IF(D16="No","Competitive parity","Undetermined beyond valuable"),IF(E16<>"Yes",IF(E16="No","Temporary advantage","Undetermined beyond rare"),IF(F16="Yes","Sustained advantage",IF(F16="No","Unexploited advantage","Undetermined beyond inimitable")))))) | J16: =IF(A16="","",IF(AND(C16="Yes",D16="Yes",E16="Yes",N(I16)<0.1),"Competence trap",IF(AND(OR(G16="Temporary advantage",G16="Unexploited advantage",G16="Sustained advantage"),N(I16)>=0.1),"Supported",IF(AND(G16="Competitive parity",N(I16)>=0.1),"Table stakes",""))))
G17: =IF(A17="","",IF(C17<>"Yes",IF(C17="No","Competitive disadvantage","Undetermined"),IF(D17<>"Yes",IF(D17="No","Competitive parity","Undetermined beyond valuable"),IF(E17<>"Yes",IF(E17="No","Temporary advantage","Undetermined beyond rare"),IF(F17="Yes","Sustained advantage",IF(F17="No","Unexploited advantage","Undetermined beyond inimitable")))))) | J17: =IF(A17="","",IF(AND(C17="Yes",D17="Yes",E17="Yes",N(I17)<0.1),"Competence trap",IF(AND(OR(G17="Temporary advantage",G17="Unexploited advantage",G17="Sustained advantage"),N(I17)>=0.1),"Supported",IF(AND(G17="Competitive parity",N(I17)>=0.1),"Table stakes",""))))
... G20: =IF(A20="","",IF(C20<>"Yes",IF(C20="No","Competitive disadvantage","Undetermined"),IF(D20<>"Yes",IF(D20="No","Competitive parity","Undetermined beyond valuable"),IF(E20<>"Yes",IF(E20="No","Temporary advantage","Undetermined beyond rare"),IF(F20="Yes","Sustained advantage",IF(F20="No","Unexploited advantage","Undetermined beyond inimitable")))))) | J20: =IF(A20="","",IF(AND(C20="Yes",D20="Yes",E20="Yes",N(I20)<0.1),"Competence trap",IF(AND(OR(G20="Temporary advantage",G20="Unexploited advantage",G20="Sustained advantage"),N(I20)>=0.1),"Supported",IF(AND(G20="Competitive parity",N(I20)>=0.1),"Table stakes",""))))

Sheet SWOT-TOWS
A1: SWOT and TOWS
A2: Every item names the finding it came from. TOWS options pair the items by ID.
A3: Blue text on cream = your inputs. Black on grey = formulas (do not type over them).
A5: ID | B5: Strengths (internal, helpful) | C5: Source | E5: ID | F5: Weaknesses (internal, harmful) | G5: Source
A6: S1 | E6: W1
A7: S2 | E7: W2
A8: S3 | E8: W3
A9: S4 | E9: W4
A10: S5 | E10: W5
A11: S6 | E11: W6
A14: ID | B14: Opportunities (external, helpful) | C14: Source | E14: ID | F14: Threats (external, harmful) | G14: Source
A15: O1 | E15: T1
A16: O2 | E16: T2
A17: O3 | E17: T3
A18: O4 | E18: T4
A19: O5 | E19: T5
A20: O6 | E20: T6
A23: Cell | B23: TOWS strategic option | C23: Pairs (e.g. S1 × O1)

Sheet Decision Matrix
A1: Decision Matrix
A2: Weight each criterion 1-5 and score each option 1-5. Include do nothing.
A3: Blue text on cream = your inputs. Black on grey = formulas (do not type over them).
A5: Criterion | B5: Weight 1-5 | C5: Tied to goal | D5: Option 1 | E5: Option 2 | F5: Option 3 | G5: Option 4 | H5: Option 5
A14: Weighted score (out of 5) | D14: =IF(COUNT(D6:D13)=0,"",SUMPRODUCT($B$6:$B$13,D6:D13)/SUMPRODUCT($B$6:$B$13*(D6:D13<>""))) | E14: =IF(COUNT(E6:E13)=0,"",SUMPRODUCT($B$6:$B$13,E6:E13)/SUMPRODUCT($B$6:$B$13*(E6:E13<>""))) | F14: =IF(COUNT(F6:F13)=0,"",SUMPRODUCT($B$6:$B$13,F6:F13)/SUMPRODUCT($B$6:$B$13*(F6:F13<>""))) | G14: =IF(COUNT(G6:G13)=0,"",SUMPRODUCT($B$6:$B$13,G6:G13)/SUMPRODUCT($B$6:$B$13*(G6:G13<>""))) | H14: =IF(COUNT(H6:H13)=0,"",SUMPRODUCT($B$6:$B$13,H6:H13)/SUMPRODUCT($B$6:$B$13*(H6:H13<>"")))
A15: Rank | D15: =IF(D14="","",RANK(D14,$D$14:$H$14)) | E15: =IF(E14="","",RANK(E14,$D$14:$H$14)) | F15: =IF(F14="","",RANK(F14,$D$14:$H$14)) | G15: =IF(G14="","",RANK(G14,$D$14:$H$14)) | H15: =IF(H14="","",RANK(H14,$D$14:$H$14))
A17: The matrix ranks; it does not choose. The recommendation is yours.

Sheet Expected Value
A1: Expected Value
A2: Probabilities as percentages that sum to 100% per option; NPV in $M. Follows the course handout 'Choosing Among Strategic Alternatives'.
A3: Blue text on cream = your inputs. Black on grey = formulas (do not type over them).
A5: Option | B5: P strong | C5: NPV strong ($M) | D5: P moderate | E5: NPV moderate ($M) | F5: P weak | G5: NPV weak ($M) | H5: Probability check | I5: Expected NPV ($M) | J5: Worst case | K5: Best case
H6: =IF(A6="","",IF(ABS(B6+D6+F6-1)<0.001,"OK","Must sum to 100%")) | I6: =IF(A6="","",B6*C6+D6*E6+F6*G6) | J6: =IF(A6="","",MIN(C6,E6,G6)) | K6: =IF(A6="","",MAX(C6,E6,G6))
H7: =IF(A7="","",IF(ABS(B7+D7+F7-1)<0.001,"OK","Must sum to 100%")) | I7: =IF(A7="","",B7*C7+D7*E7+F7*G7) | J7: =IF(A7="","",MIN(C7,E7,G7)) | K7: =IF(A7="","",MAX(C7,E7,G7))
H8: =IF(A8="","",IF(ABS(B8+D8+F8-1)<0.001,"OK","Must sum to 100%")) | I8: =IF(A8="","",B8*C8+D8*E8+F8*G8) | J8: =IF(A8="","",MIN(C8,E8,G8)) | K8: =IF(A8="","",MAX(C8,E8,G8))
H9: =IF(A9="","",IF(ABS(B9+D9+F9-1)<0.001,"OK","Must sum to 100%")) | I9: =IF(A9="","",B9*C9+D9*E9+F9*G9) | J9: =IF(A9="","",MIN(C9,E9,G9)) | K9: =IF(A9="","",MAX(C9,E9,G9))
H10: =IF(A10="","",IF(ABS(B10+D10+F10-1)<0.001,"OK","Must sum to 100%")) | I10: =IF(A10="","",B10*C10+D10*E10+F10*G10) | J10: =IF(A10="","",MIN(C10,E10,G10)) | K10: =IF(A10="","",MAX(C10,E10,G10))
H11: =IF(A11="","",IF(ABS(B11+D11+F11-1)<0.001,"OK","Must sum to 100%")) | I11: =IF(A11="","",B11*C11+D11*E11+F11*G11) | J11: =IF(A11="","",MIN(C11,E11,G11)) | K11: =IF(A11="","",MAX(C11,E11,G11))
A13: Leader on expected value | B13: =IFERROR(INDEX(A6:A11,MATCH(MAX(I6:I11),I6:I11,0)),"")
A14: Maximin choice (best worst case) | B14: =IFERROR(INDEX(A6:A11,MATCH(MAX(J6:J11),J6:J11,0)),"")
A15: Value of perfect information ($M) | B15: =IFERROR(INDEX(B6:B11,MATCH(MAX(I6:I11),I6:I11,0))*MAX(C6:C11)+INDEX(D6:D11,MATCH(MAX(I6:I11),I6:I11,0))*MAX(E6:E11)+INDEX(F6:F11,MATCH(MAX(I6:I11),I6:I11,0))*MAX(G6:G11)-MAX(I6:I11),"") | C15: The most worth paying for a pilot that reveals the scenario first (leader's probabilities).
A18: Is a pilot worth it? (Bayes' rule) | B18: How likely the pilot shows each result IF that scenario is real. Each row sums to 100%. Uses the first option's scenario probabilities as the prior.
A19: Scenario | B19: Prior | C19: P(positive | scenario) | D19: P(negative | scenario) | E19: Row check | F19: Posterior if positive | G19: Posterior if negative
A20: Strong | B20: =IF(B6="","",B6) | E20: =IF(C20="","",IF(ABS(C20+D20-1)<0.001,"OK","Must sum to 100%")) | F20: =IFERROR(B20*C20/SUMPRODUCT($B$20:$B$22,$C$20:$C$22),"") | G20: =IFERROR(B20*D20/SUMPRODUCT($B$20:$B$22,$D$20:$D$22),"")
A21: Moderate | B21: =IF(D6="","",D6) | E21: =IF(C21="","",IF(ABS(C21+D21-1)<0.001,"OK","Must sum to 100%")) | F21: =IFERROR(B21*C21/SUMPRODUCT($B$20:$B$22,$C$20:$C$22),"") | G21: =IFERROR(B21*D21/SUMPRODUCT($B$20:$B$22,$D$20:$D$22),"")
A22: Weak | B22: =IF(F6="","",F6) | E22: =IF(C22="","",IF(ABS(C22+D22-1)<0.001,"OK","Must sum to 100%")) | F22: =IFERROR(B22*C22/SUMPRODUCT($B$20:$B$22,$C$20:$C$22),"") | G22: =IFERROR(B22*D22/SUMPRODUCT($B$20:$B$22,$D$20:$D$22),"")
A23: P(result) | F23: =IFERROR(SUMPRODUCT(B20:B22,C20:C22),"") -> 0 | G23: =IFERROR(SUMPRODUCT(B20:B22,D20:D22),"") -> 0
A25: Option | B25: Expected NPV now | C25: If positive | D25: If negative
A26: =IF(A6="","",A6) | B26: =IF(A6="","",I6) | C26: =IF(OR(A6="",F20=""),"",C6*F20+E6*F21+G6*F22) | D26: =IF(OR(A6="",G20=""),"",C6*G20+E6*G21+G6*G22)
A27: =IF(A7="","",A7) | B27: =IF(A7="","",I7) | C27: =IF(OR(A7="",F20=""),"",C7*F20+E7*F21+G7*F22) | D27: =IF(OR(A7="",G20=""),"",C7*G20+E7*G21+G7*G22)
A28: =IF(A8="","",A8) | B28: =IF(A8="","",I8) | C28: =IF(OR(A8="",F20=""),"",C8*F20+E8*F21+G8*F22) | D28: =IF(OR(A8="",G20=""),"",C8*G20+E8*G21+G8*G22)
A29: =IF(A9="","",A9) | B29: =IF(A9="","",I9) | C29: =IF(OR(A9="",F20=""),"",C9*F20+E9*F21+G9*F22) | D29: =IF(OR(A9="",G20=""),"",C9*G20+E9*G21+G9*G22)
A30: =IF(A10="","",A10) | B30: =IF(A10="","",I10) | C30: =IF(OR(A10="",F20=""),"",C10*F20+E10*F21+G10*F22) | D30: =IF(OR(A10="",G20=""),"",C10*G20+E10*G21+G10*G22)
A31: =IF(A11="","",A11) | B31: =IF(A11="","",I11) | C31: =IF(OR(A11="",F20=""),"",C11*F20+E11*F21+G11*F22) | D31: =IF(OR(A11="",G20=""),"",C11*G20+E11*G21+G11*G22)
A33: Best option if the pilot is positive | B33: =IFERROR(INDEX(A26:A31,MATCH(MAX(C26:C31),C26:C31,0)),"") | C33: If both results point to the same option, the pilot cannot change the choice and is worth nothing for this decision.
A34: Best option if the pilot is negative | B34: =IFERROR(INDEX(A26:A31,MATCH(MAX(D26:D31),D26:D31,0)),"")
A35: Expected NPV with the pilot ($M) | B35: =IFERROR(F23*MAX(C26:C31)+G23*MAX(D26:D31),"") -> 0
A36: Value of the pilot, EVSI ($M) | B36: =IFERROR(B35-MAX(I6:I11),"") -> 0
A37: Pilot cost ($M)
A38: Net value of running the pilot ($M) | B38: =IFERROR(IF(B37="","",B36-B37),"")
A39: Share of perfect information | B39: =IFERROR(B36/B15,"")

Sheet Business Case
A1: Business Case
A2: One option. Year 0 is the investment year. Working capital is released in the final year. Money in $.
A3: Blue text on cream = your inputs. Black on grey = formulas (do not type over them).
A5: Assumptions
A6: Discount rate
A7: Tax rate
A8: Working capital (% of revenue)
A10: $ | B10: Year 0 | C10: Year 1 | D10: Year 2 | E10: Year 3 | F10: Year 4 | G10: Year 5
A11: Units
A12: Price per unit
A13: Variable cost per unit
A14: Fixed costs
A15: Capex
A16: Revenue | B16: =B11*B12 -> 0 | C16: =C11*C12 -> 0 | D16: =D11*D12 -> 0 | E16: =E11*E12 -> 0 | F16: =F11*F12 -> 0 | G16: =G11*G12 -> 0
A17: Contribution | B17: =B11*(B12-B13) -> 0 | C17: =C11*(C12-C13) -> 0 | D17: =D11*(D12-D13) -> 0 | E17: =E11*(E12-E13) -> 0 | F17: =F11*(F12-F13) -> 0 | G17: =G11*(G12-G13) -> 0
A18: Operating profit (EBIT) | B18: =B17-B14 -> 0 | C18: =C17-C14 -> 0 | D18: =D17-D14 -> 0 | E18: =E17-E14 -> 0 | F18: =F17-F14 -> 0 | G18: =G17-G14 -> 0
A19: Tax | B19: =MAX(0,B18)*$B$7 -> 0 | C19: =MAX(0,C18)*$B$7 -> 0 | D19: =MAX(0,D18)*$B$7 -> 0 | E19: =MAX(0,E18)*$B$7 -> 0 | F19: =MAX(0,F18)*$B$7 -> 0 | G19: =MAX(0,G18)*$B$7 -> 0
A20: Working capital | B20: =B16*$B$8 -> 0 | C20: =C16*$B$8 -> 0 | D20: =D16*$B$8 -> 0 | E20: =E16*$B$8 -> 0 | F20: =F16*$B$8 -> 0 | G20: =G16*$B$8 -> 0
A21: Change in working capital | B21: =B20 -> 0 | C21: =C20-B20 -> 0 | D21: =D20-C20 -> 0 | E21: =E20-D20 -> 0 | F21: =F20-E20 -> 0 | G21: =G20-F20 -> 0
A22: Cash flow | B22: =B18-B19-B21-B15 -> 0 | C22: =C18-C19-C21-C15 -> 0 | D22: =D18-D19-D21-D15 -> 0 | E22: =E18-E19-E21-E15 -> 0 | F22: =F18-F19-F21-F15 -> 0 | G22: =G18-G19-G21-G15+G20 -> 0
A23: Cumulative cash flow | B23: =B22 -> 0 | C23: =B23+C22 -> 0 | D23: =C23+D22 -> 0 | E23: =D23+E22 -> 0 | F23: =E23+F22 -> 0 | G23: =F23+G22 -> 0
A25: NPV | B25: =IF(COUNT(B11:G11)=0,"",B22+NPV($B$6,C22:G22))
A26: IRR | B26: =IFERROR(IRR(B22:G22),"n/a") -> n/a
A27: Clears the hurdle? | B27: =IF(ISNUMBER(B26),IF(B26>=$B$6,"Yes","No"),"")
A29: State the break-even in words in your exhibit (the Business Case skill computes it).

Sheet Risk Analysis
A1: Risk Analysis (Exhibit Q-3)
A2: Works on the Business Case sheet. Set a low / likely / high for each driver: % change from plan, except the discount rate (an absolute rate). Blank = no uncertainty.
A3: Blue text on cream = your inputs. Black on grey = formulas (do not type over them).
A5: Driver | B5: Low | C5: Likely | D5: High | E5: Eff. low | F5: Eff. likely | G5: Eff. high
A6: Price per unit | E6: =IF(B6="",F6,B6) -> 0 | F6: =IF(C6="",0,C6) -> 0 | G6: =IF(D6="",F6,D6) -> 0
A7: Units | E7: =IF(B7="",F7,B7) -> 0 | F7: =IF(C7="",0,C7) -> 0 | G7: =IF(D7="",F7,D7) -> 0
A8: Variable cost per unit | E8: =IF(B8="",F8,B8) -> 0 | F8: =IF(C8="",0,C8) -> 0 | G8: =IF(D8="",F8,D8) -> 0
A9: Fixed costs | E9: =IF(B9="",F9,B9) -> 0 | F9: =IF(C9="",0,C9) -> 0 | G9: =IF(D9="",F9,D9) -> 0
A10: Capex | E10: =IF(B10="",F10,B10) -> 0 | F10: =IF(C10="",0,C10) -> 0 | G10: =IF(D10="",F10,D10) -> 0
A11: Discount rate (absolute) | E11: =IF(B11="",F11,B11) -> 0 | F11: =IF(C11="",'Business Case'!$B$6,C11) -> 0 | G11: =IF(D11="",F11,D11) -> 0
A12: Range check | B12: =IF(SUMPRODUCT((E6:E11>F6:F11)+(F6:F11>G6:G11))=0,"OK","Need low <= likely <= high") -> OK
A14: Tornado: NPV with one driver at its low or high, the others at plan
A15: Scenario | B15: Price × | C15: Units × | D15: Var. cost × | E15: Fixed × | F15: Capex × | G15: Rate | H15: CF Y0 | I15: CF Y1 | J15: CF Y2 | K15: CF Y3 | L15: CF Y4 | M15: CF Y5 | N15: NPV
A16: Plan | B16: =1 -> 1 | C16: =1 -> 1 | D16: =1 -> 1 | E16: =1 -> 1 | F16: =1 -> 1 | G16: ='Business Case'!$B$6 -> 0 | H16: =(('Business Case'!B11*$C16*'Business Case'!B12*$B16)-'Business Case'!B11*$C16*'Business Case'!B13*$D16-'Business Case'!B14*$E16)-MAX(0,(('Business Case'!B11*$C16*'Business Case'!B12*$B16)-'Business Case'!B11*$C16*'Business Case'!B13*$D16-'Business Case'!B14*$E16))*'Business Case'!$B$7-'Business Case'!$B$8*('Business Case'!B11*$C16*'Business Case'!B12*$B16)-'Business Case'!B15*$F16 -> 0 | I16: =(('Business Case'!C11*$C16*'Business Case'!C12*$B16)-'Business Case'!C11*$C16*'Business Case'!C13*$D16-'Business Case'!C14*$E16)-MAX(0,(('Business Case'!C11*$C16*'Business Case'!C12*$B16)-'Business Case'!C11*$C16*'Business Case'!C13*$D16-'Business Case'!C14*$E16))*'Business Case'!$B$7-'Business Case'!$B$8*(('Business Case'!C11*$C16*'Business Case'!C12*$B16)-('Business Case'!B11*$C16*'Business Case'!B12*$B16))-'Business Case'!C15*$F16 -> 0 | J16: =(('Business Case'!D11*$C16*'Business Case'!D12*$B16)-'Business Case'!D11*$C16*'Business Case'!D13*$D16-'Business Case'!D14*$E16)-MAX(0,(('Business Case'!D11*$C16*'Business Case'!D12*$B16)-'Business Case'!D11*$C16*'Business Case'!D13*$D16-'Business Case'!D14*$E16))*'Business Case'!$B$7-'Business Case'!$B$8*(('Business Case'!D11*$C16*'Business Case'!D12*$B16)-('Business Case'!C11*$C16*'Business Case'!C12*$B16))-'Business Case'!D15*$F16 -> 0 | K16: =(('Business Case'!E11*$C16*'Business Case'!E12*$B16)-'Business Case'!E11*$C16*'Business Case'!E13*$D16-'Business Case'!E14*$E16)-MAX(0,(('Business Case'!E11*$C16*'Business Case'!E12*$B16)-'Business Case'!E11*$C16*'Business Case'!E13*$D16-'Business Case'!E14*$E16))*'Business Case'!$B$7-'Business Case'!$B$8*(('Business Case'!E11*$C16*'Business Case'!E12*$B16)-('Business Case'!D11*$C16*'Business Case'!D12*$B16))-'Business Case'!E15*$F16 -> 0 | L16: =(('Business Case'!F11*$C16*'Business Case'!F12*$B16)-'Business Case'!F11*$C16*'Business Case'!F13*$D16-'Business Case'!F14*$E16)-MAX(0,(('Business Case'!F11*$C16*'Business Case'!F12*$B16)-'Business Case'!F11*$C16*'Business Case'!F13*$D16-'Business Case'!F14*$E16))*'Business Case'!$B$7-'Business Case'!$B$8*(('Business Case'!F11*$C16*'Business Case'!F12*$B16)-('Business Case'!E11*$C16*'Business Case'!E12*$B16))-'Business Case'!F15*$F16 -> 0 | M16: =(('Business Case'!G11*$C16*'Business Case'!G12*$B16)-'Business Case'!G11*$C16*'Business Case'!G13*$D16-'Business Case'!G14*$E16)-MAX(0,(('Business Case'!G11*$C16*'Business Case'!G12*$B16)-'Business Case'!G11*$C16*'Business Case'!G13*$D16-'Business Case'!G14*$E16))*'Business Case'!$B$7-'Business Case'!$B$8*(('Business Case'!G11*$C16*'Business Case'!G12*$B16)-('Business Case'!F11*$C16*'Business Case'!F12*$B16))-'Business Case'!G15*$F16+'Business Case'!$B$8*('Business Case'!G11*$C16*'Business Case'!G12*$B16) -> 0 | N16: =IF(COUNT('Business Case'!B11:G11)=0,"",H16+NPV(G16,I16:M16))
A17: Price per unit low | B17: =1+E6 -> 1 | C17: =1 -> 1 | D17: =1 -> 1 | E17: =1 -> 1 | F17: =1 -> 1 | G17: ='Business Case'!$B$6 -> 0 | H17: =(('Business Case'!B11*$C17*'Business Case'!B12*$B17)-'Business Case'!B11*$C17*'Business Case'!B13*$D17-'Business Case'!B14*$E17)-MAX(0,(('Business Case'!B11*$C17*'Business Case'!B12*$B17)-'Business Case'!B11*$C17*'Business Case'!B13*$D17-'Business Case'!B14*$E17))*'Business Case'!$B$7-'Business Case'!$B$8*('Business Case'!B11*$C17*'Business Case'!B12*$B17)-'Business Case'!B15*$F17 -> 0 | I17: =(('Business Case'!C11*$C17*'Business Case'!C12*$B17)-'Business Case'!C11*$C17*'Business Case'!C13*$D17-'Business Case'!C14*$E17)-MAX(0,(('Business Case'!C11*$C17*'Business Case'!C12*$B17)-'Business Case'!C11*$C17*'Business Case'!C13*$D17-'Business Case'!C14*$E17))*'Business Case'!$B$7-'Business Case'!$B$8*(('Business Case'!C11*$C17*'Business Case'!C12*$B17)-('Business Case'!B11*$C17*'Business Case'!B12*$B17))-'Business Case'!C15*$F17 -> 0 | J17: =(('Business Case'!D11*$C17*'Business Case'!D12*$B17)-'Business Case'!D11*$C17*'Business Case'!D13*$D17-'Business Case'!D14*$E17)-MAX(0,(('Business Case'!D11*$C17*'Business Case'!D12*$B17)-'Business Case'!D11*$C17*'Business Case'!D13*$D17-'Business Case'!D14*$E17))*'Business Case'!$B$7-'Business Case'!$B$8*(('Business Case'!D11*$C17*'Business Case'!D12*$B17)-('Business Case'!C11*$C17*'Business Case'!C12*$B17))-'Business Case'!D15*$F17 -> 0 | K17: =(('Business Case'!E11*$C17*'Business Case'!E12*$B17)-'Business Case'!E11*$C17*'Business Case'!E13*$D17-'Business Case'!E14*$E17)-MAX(0,(('Business Case'!E11*$C17*'Business Case'!E12*$B17)-'Business Case'!E11*$C17*'Business Case'!E13*$D17-'Business Case'!E14*$E17))*'Business Case'!$B$7-'Business Case'!$B$8*(('Business Case'!E11*$C17*'Business Case'!E12*$B17)-('Business Case'!D11*$C17*'Business Case'!D12*$B17))-'Business Case'!E15*$F17 -> 0 | L17: =(('Business Case'!F11*$C17*'Business Case'!F12*$B17)-'Business Case'!F11*$C17*'Business Case'!F13*$D17-'Business Case'!F14*$E17)-MAX(0,(('Business Case'!F11*$C17*'Business Case'!F12*$B17)-'Business Case'!F11*$C17*'Business Case'!F13*$D17-'Business Case'!F14*$E17))*'Business Case'!$B$7-'Business Case'!$B$8*(('Business Case'!F11*$C17*'Business Case'!F12*$B17)-('Business Case'!E11*$C17*'Business Case'!E12*$B17))-'Business Case'!F15*$F17 -> 0 | M17: =(('Business Case'!G11*$C17*'Business Case'!G12*$B17)-'Business Case'!G11*$C17*'Business Case'!G13*$D17-'Business Case'!G14*$E17)-MAX(0,(('Business Case'!G11*$C17*'Business Case'!G12*$B17)-'Business Case'!G11*$C17*'Business Case'!G13*$D17-'Business Case'!G14*$E17))*'Business Case'!$B$7-'Business Case'!$B$8*(('Business Case'!G11*$C17*'Business Case'!G12*$B17)-('Business Case'!F11*$C17*'Business Case'!F12*$B17))-'Business Case'!G15*$F17+'Business Case'!$B$8*('Business Case'!G11*$C17*'Business Case'!G12*$B17) -> 0 | N17: =IF(COUNT('Business Case'!B11:G11)=0,"",H17+NPV(G17,I17:M17))
A18: Price per unit high | B18: =1+G6 -> 1 | C18: =1 -> 1 | D18: =1 -> 1 | E18: =1 -> 1 | F18: =1 -> 1 | G18: ='Business Case'!$B$6 -> 0 | H18: =(('Business Case'!B11*$C18*'Business Case'!B12*$B18)-'Business Case'!B11*$C18*'Business Case'!B13*$D18-'Business Case'!B14*$E18)-MAX(0,(('Business Case'!B11*$C18*'Business Case'!B12*$B18)-'Business Case'!B11*$C18*'Business Case'!B13*$D18-'Business Case'!B14*$E18))*'Business Case'!$B$7-'Business Case'!$B$8*('Business Case'!B11*$C18*'Business Case'!B12*$B18)-'Business Case'!B15*$F18 -> 0 | I18: =(('Business Case'!C11*$C18*'Business Case'!C12*$B18)-'Business Case'!C11*$C18*'Business Case'!C13*$D18-'Business Case'!C14*$E18)-MAX(0,(('Business Case'!C11*$C18*'Business Case'!C12*$B18)-'Business Case'!C11*$C18*'Business Case'!C13*$D18-'Business Case'!C14*$E18))*'Business Case'!$B$7-'Business Case'!$B$8*(('Business Case'!C11*$C18*'Business Case'!C12*$B18)-('Business Case'!B11*$C18*'Business Case'!B12*$B18))-'Business Case'!C15*$F18 -> 0 | J18: =(('Business Case'!D11*$C18*'Business Case'!D12*$B18)-'Business Case'!D11*$C18*'Business Case'!D13*$D18-'Business Case'!D14*$E18)-MAX(0,(('Business Case'!D11*$C18*'Business Case'!D12*$B18)-'Business Case'!D11*$C18*'Business Case'!D13*$D18-'Business Case'!D14*$E18))*'Business Case'!$B$7-'Business Case'!$B$8*(('Business Case'!D11*$C18*'Business Case'!D12*$B18)-('Business Case'!C11*$C18*'Business Case'!C12*$B18))-'Business Case'!D15*$F18 -> 0 | K18: =(('Business Case'!E11*$C18*'Business Case'!E12*$B18)-'Business Case'!E11*$C18*'Business Case'!E13*$D18-'Business Case'!E14*$E18)-MAX(0,(('Business Case'!E11*$C18*'Business Case'!E12*$B18)-'Business Case'!E11*$C18*'Business Case'!E13*$D18-'Business Case'!E14*$E18))*'Business Case'!$B$7-'Business Case'!$B$8*(('Business Case'!E11*$C18*'Business Case'!E12*$B18)-('Business Case'!D11*$C18*'Business Case'!D12*$B18))-'Business Case'!E15*$F18 -> 0 | L18: =(('Business Case'!F11*$C18*'Business Case'!F12*$B18)-'Business Case'!F11*$C18*'Business Case'!F13*$D18-'Business Case'!F14*$E18)-MAX(0,(('Business Case'!F11*$C18*'Business Case'!F12*$B18)-'Business Case'!F11*$C18*'Business Case'!F13*$D18-'Business Case'!F14*$E18))*'Business Case'!$B$7-'Business Case'!$B$8*(('Business Case'!F11*$C18*'Business Case'!F12*$B18)-('Business Case'!E11*$C18*'Business Case'!E12*$B18))-'Business Case'!F15*$F18 -> 0 | M18: =(('Business Case'!G11*$C18*'Business Case'!G12*$B18)-'Business Case'!G11*$C18*'Business Case'!G13*$D18-'Business Case'!G14*$E18)-MAX(0,(('Business Case'!G11*$C18*'Business Case'!G12*$B18)-'Business Case'!G11*$C18*'Business Case'!G13*$D18-'Business Case'!G14*$E18))*'Business Case'!$B$7-'Business Case'!$B$8*(('Business Case'!G11*$C18*'Business Case'!G12*$B18)-('Business Case'!F11*$C18*'Business Case'!F12*$B18))-'Business Case'!G15*$F18+'Business Case'!$B$8*('Business Case'!G11*$C18*'Business Case'!G12*$B18) -> 0 | N18: =IF(COUNT('Business Case'!B11:G11)=0,"",H18+NPV(G18,I18:M18))
A19: Units low | B19: =1 -> 1 | C19: =1+E7 -> 1 | D19: =1 -> 1 | E19: =1 -> 1 | F19: =1 -> 1 | G19: ='Business Case'!$B$6 -> 0 | H19: =(('Business Case'!B11*$C19*'Business Case'!B12*$B19)-'Business Case'!B11*$C19*'Business Case'!B13*$D19-'Business Case'!B14*$E19)-MAX(0,(('Business Case'!B11*$C19*'Business Case'!B12*$B19)-'Business Case'!B11*$C19*'Business Case'!B13*$D19-'Business Case'!B14*$E19))*'Business Case'!$B$7-'Business Case'!$B$8*('Business Case'!B11*$C19*'Business Case'!B12*$B19)-'Business Case'!B15*$F19 -> 0 | I19: =(('Business Case'!C11*$C19*'Business Case'!C12*$B19)-'Business Case'!C11*$C19*'Business Case'!C13*$D19-'Business Case'!C14*$E19)-MAX(0,(('Business Case'!C11*$C19*'Business Case'!C12*$B19)-'Business Case'!C11*$C19*'Business Case'!C13*$D19-'Business Case'!C14*$E19))*'Business Case'!$B$7-'Business Case'!$B$8*(('Business Case'!C11*$C19*'Business Case'!C12*$B19)-('Business Case'!B11*$C19*'Business Case'!B12*$B19))-'Business Case'!C15*$F19 -> 0 | J19: =(('Business Case'!D11*$C19*'Business Case'!D12*$B19)-'Business Case'!D11*$C19*'Business Case'!D13*$D19-'Business Case'!D14*$E19)-MAX(0,(('Business Case'!D11*$C19*'Business Case'!D12*$B19)-'Business Case'!D11*$C19*'Business Case'!D13*$D19-'Business Case'!D14*$E19))*'Business Case'!$B$7-'Business Case'!$B$8*(('Business Case'!D11*$C19*'Business Case'!D12*$B19)-('Business Case'!C11*$C19*'Business Case'!C12*$B19))-'Business Case'!D15*$F19 -> 0 | K19: =(('Business Case'!E11*$C19*'Business Case'!E12*$B19)-'Business Case'!E11*$C19*'Business Case'!E13*$D19-'Business Case'!E14*$E19)-MAX(0,(('Business Case'!E11*$C19*'Business Case'!E12*$B19)-'Business Case'!E11*$C19*'Business Case'!E13*$D19-'Business Case'!E14*$E19))*'Business Case'!$B$7-'Business Case'!$B$8*(('Business Case'!E11*$C19*'Business Case'!E12*$B19)-('Business Case'!D11*$C19*'Business Case'!D12*$B19))-'Business Case'!E15*$F19 -> 0 | L19: =(('Business Case'!F11*$C19*'Business Case'!F12*$B19)-'Business Case'!F11*$C19*'Business Case'!F13*$D19-'Business Case'!F14*$E19)-MAX(0,(('Business Case'!F11*$C19*'Business Case'!F12*$B19)-'Business Case'!F11*$C19*'Business Case'!F13*$D19-'Business Case'!F14*$E19))*'Business Case'!$B$7-'Business Case'!$B$8*(('Business Case'!F11*$C19*'Business Case'!F12*$B19)-('Business Case'!E11*$C19*'Business Case'!E12*$B19))-'Business Case'!F15*$F19 -> 0 | M19: =(('Business Case'!G11*$C19*'Business Case'!G12*$B19)-'Business Case'!G11*$C19*'Business Case'!G13*$D19-'Business Case'!G14*$E19)-MAX(0,(('Business Case'!G11*$C19*'Business Case'!G12*$B19)-'Business Case'!G11*$C19*'Business Case'!G13*$D19-'Business Case'!G14*$E19))*'Business Case'!$B$7-'Business Case'!$B$8*(('Business Case'!G11*$C19*'Business Case'!G12*$B19)-('Business Case'!F11*$C19*'Business Case'!F12*$B19))-'Business Case'!G15*$F19+'Business Case'!$B$8*('Business Case'!G11*$C19*'Business Case'!G12*$B19) -> 0 | N19: =IF(COUNT('Business Case'!B11:G11)=0,"",H19+NPV(G19,I19:M19))
A20: Units high | B20: =1 -> 1 | C20: =1+G7 -> 1 | D20: =1 -> 1 | E20: =1 -> 1 | F20: =1 -> 1 | G20: ='Business Case'!$B$6 -> 0 | H20: =(('Business Case'!B11*$C20*'Business Case'!B12*$B20)-'Business Case'!B11*$C20*'Business Case'!B13*$D20-'Business Case'!B14*$E20)-MAX(0,(('Business Case'!B11*$C20*'Business Case'!B12*$B20)-'Business Case'!B11*$C20*'Business Case'!B13*$D20-'Business Case'!B14*$E20))*'Business Case'!$B$7-'Business Case'!$B$8*('Business Case'!B11*$C20*'Business Case'!B12*$B20)-'Business Case'!B15*$F20 -> 0 | I20: =(('Business Case'!C11*$C20*'Business Case'!C12*$B20)-'Business Case'!C11*$C20*'Business Case'!C13*$D20-'Business Case'!C14*$E20)-MAX(0,(('Business Case'!C11*$C20*'Business Case'!C12*$B20)-'Business Case'!C11*$C20*'Business Case'!C13*$D20-'Business Case'!C14*$E20))*'Business Case'!$B$7-'Business Case'!$B$8*(('Business Case'!C11*$C20*'Business Case'!C12*$B20)-('Business Case'!B11*$C20*'Business Case'!B12*$B20))-'Business Case'!C15*$F20 -> 0 | J20: =(('Business Case'!D11*$C20*'Business Case'!D12*$B20)-'Business Case'!D11*$C20*'Business Case'!D13*$D20-'Business Case'!D14*$E20)-MAX(0,(('Business Case'!D11*$C20*'Business Case'!D12*$B20)-'Business Case'!D11*$C20*'Business Case'!D13*$D20-'Business Case'!D14*$E20))*'Business Case'!$B$7-'Business Case'!$B$8*(('Business Case'!D11*$C20*'Business Case'!D12*$B20)-('Business Case'!C11*$C20*'Business Case'!C12*$B20))-'Business Case'!D15*$F20 -> 0 | K20: =(('Business Case'!E11*$C20*'Business Case'!E12*$B20)-'Business Case'!E11*$C20*'Business Case'!E13*$D20-'Business Case'!E14*$E20)-MAX(0,(('Business Case'!E11*$C20*'Business Case'!E12*$B20)-'Business Case'!E11*$C20*'Business Case'!E13*$D20-'Business Case'!E14*$E20))*'Business Case'!$B$7-'Business Case'!$B$8*(('Business Case'!E11*$C20*'Business Case'!E12*$B20)-('Business Case'!D11*$C20*'Business Case'!D12*$B20))-'Business Case'!E15*$F20 -> 0 | L20: =(('Business Case'!F11*$C20*'Business Case'!F12*$B20)-'Business Case'!F11*$C20*'Business Case'!F13*$D20-'Business Case'!F14*$E20)-MAX(0,(('Business Case'!F11*$C20*'Business Case'!F12*$B20)-'Business Case'!F11*$C20*'Business Case'!F13*$D20-'Business Case'!F14*$E20))*'Business Case'!$B$7-'Business Case'!$B$8*(('Business Case'!F11*$C20*'Business Case'!F12*$B20)-('Business Case'!E11*$C20*'Business Case'!E12*$B20))-'Business Case'!F15*$F20 -> 0 | M20: =(('Business Case'!G11*$C20*'Business Case'!G12*$B20)-'Business Case'!G11*$C20*'Business Case'!G13*$D20-'Business Case'!G14*$E20)-MAX(0,(('Business Case'!G11*$C20*'Business Case'!G12*$B20)-'Business Case'!G11*$C20*'Business Case'!G13*$D20-'Business Case'!G14*$E20))*'Business Case'!$B$7-'Business Case'!$B$8*(('Business Case'!G11*$C20*'Business Case'!G12*$B20)-('Business Case'!F11*$C20*'Business Case'!F12*$B20))-'Business Case'!G15*$F20+'Business Case'!$B$8*('Business Case'!G11*$C20*'Business Case'!G12*$B20) -> 0 | N20: =IF(COUNT('Business Case'!B11:G11)=0,"",H20+NPV(G20,I20:M20))
A21: Variable cost per unit low | B21: =1 -> 1 | C21: =1 -> 1 | D21: =1+E8 -> 1 | E21: =1 -> 1 | F21: =1 -> 1 | G21: ='Business Case'!$B$6 -> 0 | H21: =(('Business Case'!B11*$C21*'Business Case'!B12*$B21)-'Business Case'!B11*$C21*'Business Case'!B13*$D21-'Business Case'!B14*$E21)-MAX(0,(('Business Case'!B11*$C21*'Business Case'!B12*$B21)-'Business Case'!B11*$C21*'Business Case'!B13*$D21-'Business Case'!B14*$E21))*'Business Case'!$B$7-'Business Case'!$B$8*('Business Case'!B11*$C21*'Business Case'!B12*$B21)-'Business Case'!B15*$F21 -> 0 | I21: =(('Business Case'!C11*$C21*'Business Case'!C12*$B21)-'Business Case'!C11*$C21*'Business Case'!C13*$D21-'Business Case'!C14*$E21)-MAX(0,(('Business Case'!C11*$C21*'Business Case'!C12*$B21)-'Business Case'!C11*$C21*'Business Case'!C13*$D21-'Business Case'!C14*$E21))*'Business Case'!$B$7-'Business Case'!$B$8*(('Business Case'!C11*$C21*'Business Case'!C12*$B21)-('Business Case'!B11*$C21*'Business Case'!B12*$B21))-'Business Case'!C15*$F21 -> 0 | J21: =(('Business Case'!D11*$C21*'Business Case'!D12*$B21)-'Business Case'!D11*$C21*'Business Case'!D13*$D21-'Business Case'!D14*$E21)-MAX(0,(('Business Case'!D11*$C21*'Business Case'!D12*$B21)-'Business Case'!D11*$C21*'Business Case'!D13*$D21-'Business Case'!D14*$E21))*'Business Case'!$B$7-'Business Case'!$B$8*(('Business Case'!D11*$C21*'Business Case'!D12*$B21)-('Business Case'!C11*$C21*'Business Case'!C12*$B21))-'Business Case'!D15*$F21 -> 0 | K21: =(('Business Case'!E11*$C21*'Business Case'!E12*$B21)-'Business Case'!E11*$C21*'Business Case'!E13*$D21-'Business Case'!E14*$E21)-MAX(0,(('Business Case'!E11*$C21*'Business Case'!E12*$B21)-'Business Case'!E11*$C21*'Business Case'!E13*$D21-'Business Case'!E14*$E21))*'Business Case'!$B$7-'Business Case'!$B$8*(('Business Case'!E11*$C21*'Business Case'!E12*$B21)-('Business Case'!D11*$C21*'Business Case'!D12*$B21))-'Business Case'!E15*$F21 -> 0 | L21: =(('Business Case'!F11*$C21*'Business Case'!F12*$B21)-'Business Case'!F11*$C21*'Business Case'!F13*$D21-'Business Case'!F14*$E21)-MAX(0,(('Business Case'!F11*$C21*'Business Case'!F12*$B21)-'Business Case'!F11*$C21*'Business Case'!F13*$D21-'Business Case'!F14*$E21))*'Business Case'!$B$7-'Business Case'!$B$8*(('Business Case'!F11*$C21*'Business Case'!F12*$B21)-('Business Case'!E11*$C21*'Business Case'!E12*$B21))-'Business Case'!F15*$F21 -> 0 | M21: =(('Business Case'!G11*$C21*'Business Case'!G12*$B21)-'Business Case'!G11*$C21*'Business Case'!G13*$D21-'Business Case'!G14*$E21)-MAX(0,(('Business Case'!G11*$C21*'Business Case'!G12*$B21)-'Business Case'!G11*$C21*'Business Case'!G13*$D21-'Business Case'!G14*$E21))*'Business Case'!$B$7-'Business Case'!$B$8*(('Business Case'!G11*$C21*'Business Case'!G12*$B21)-('Business Case'!F11*$C21*'Business Case'!F12*$B21))-'Business Case'!G15*$F21+'Business Case'!$B$8*('Business Case'!G11*$C21*'Business Case'!G12*$B21) -> 0 | N21: =IF(COUNT('Business Case'!B11:G11)=0,"",H21+NPV(G21,I21:M21))
A22: Variable cost per unit high | B22: =1 -> 1 | C22: =1 -> 1 | D22: =1+G8 -> 1 | E22: =1 -> 1 | F22: =1 -> 1 | G22: ='Business Case'!$B$6 -> 0 | H22: =(('Business Case'!B11*$C22*'Business Case'!B12*$B22)-'Business Case'!B11*$C22*'Business Case'!B13*$D22-'Business Case'!B14*$E22)-MAX(0,(('Business Case'!B11*$C22*'Business Case'!B12*$B22)-'Business Case'!B11*$C22*'Business Case'!B13*$D22-'Business Case'!B14*$E22))*'Business Case'!$B$7-'Business Case'!$B$8*('Business Case'!B11*$C22*'Business Case'!B12*$B22)-'Business Case'!B15*$F22 -> 0 | I22: =(('Business Case'!C11*$C22*'Business Case'!C12*$B22)-'Business Case'!C11*$C22*'Business Case'!C13*$D22-'Business Case'!C14*$E22)-MAX(0,(('Business Case'!C11*$C22*'Business Case'!C12*$B22)-'Business Case'!C11*$C22*'Business Case'!C13*$D22-'Business Case'!C14*$E22))*'Business Case'!$B$7-'Business Case'!$B$8*(('Business Case'!C11*$C22*'Business Case'!C12*$B22)-('Business Case'!B11*$C22*'Business Case'!B12*$B22))-'Business Case'!C15*$F22 -> 0 | J22: =(('Business Case'!D11*$C22*'Business Case'!D12*$B22)-'Business Case'!D11*$C22*'Business Case'!D13*$D22-'Business Case'!D14*$E22)-MAX(0,(('Business Case'!D11*$C22*'Business Case'!D12*$B22)-'Business Case'!D11*$C22*'Business Case'!D13*$D22-'Business Case'!D14*$E22))*'Business Case'!$B$7-'Business Case'!$B$8*(('Business Case'!D11*$C22*'Business Case'!D12*$B22)-('Business Case'!C11*$C22*'Business Case'!C12*$B22))-'Business Case'!D15*$F22 -> 0 | K22: =(('Business Case'!E11*$C22*'Business Case'!E12*$B22)-'Business Case'!E11*$C22*'Business Case'!E13*$D22-'Business Case'!E14*$E22)-MAX(0,(('Business Case'!E11*$C22*'Business Case'!E12*$B22)-'Business Case'!E11*$C22*'Business Case'!E13*$D22-'Business Case'!E14*$E22))*'Business Case'!$B$7-'Business Case'!$B$8*(('Business Case'!E11*$C22*'Business Case'!E12*$B22)-('Business Case'!D11*$C22*'Business Case'!D12*$B22))-'Business Case'!E15*$F22 -> 0 | L22: =(('Business Case'!F11*$C22*'Business Case'!F12*$B22)-'Business Case'!F11*$C22*'Business Case'!F13*$D22-'Business Case'!F14*$E22)-MAX(0,(('Business Case'!F11*$C22*'Business Case'!F12*$B22)-'Business Case'!F11*$C22*'Business Case'!F13*$D22-'Business Case'!F14*$E22))*'Business Case'!$B$7-'Business Case'!$B$8*(('Business Case'!F11*$C22*'Business Case'!F12*$B22)-('Business Case'!E11*$C22*'Business Case'!E12*$B22))-'Business Case'!F15*$F22 -> 0 | M22: =(('Business Case'!G11*$C22*'Business Case'!G12*$B22)-'Business Case'!G11*$C22*'Business Case'!G13*$D22-'Business Case'!G14*$E22)-MAX(0,(('Business Case'!G11*$C22*'Business Case'!G12*$B22)-'Business Case'!G11*$C22*'Business Case'!G13*$D22-'Business Case'!G14*$E22))*'Business Case'!$B$7-'Business Case'!$B$8*(('Business Case'!G11*$C22*'Business Case'!G12*$B22)-('Business Case'!F11*$C22*'Business Case'!F12*$B22))-'Business Case'!G15*$F22+'Business Case'!$B$8*('Business Case'!G11*$C22*'Business Case'!G12*$B22) -> 0 | N22: =IF(COUNT('Business Case'!B11:G11)=0,"",H22+NPV(G22,I22:M22))
A23: Fixed costs low | B23: =1 -> 1 | C23: =1 -> 1 | D23: =1 -> 1 | E23: =1+E9 -> 1 | F23: =1 -> 1 | G23: ='Business Case'!$B$6 -> 0 | H23: =(('Business Case'!B11*$C23*'Business Case'!B12*$B23)-'Business Case'!B11*$C23*'Business Case'!B13*$D23-'Business Case'!B14*$E23)-MAX(0,(('Business Case'!B11*$C23*'Business Case'!B12*$B23)-'Business Case'!B11*$C23*'Business Case'!B13*$D23-'Business Case'!B14*$E23))*'Business Case'!$B$7-'Business Case'!$B$8*('Business Case'!B11*$C23*'Business Case'!B12*$B23)-'Business Case'!B15*$F23 -> 0 | I23: =(('Business Case'!C11*$C23*'Business Case'!C12*$B23)-'Business Case'!C11*$C23*'Business Case'!C13*$D23-'Business Case'!C14*$E23)-MAX(0,(('Business Case'!C11*$C23*'Business Case'!C12*$B23)-'Business Case'!C11*$C23*'Business Case'!C13*$D23-'Business Case'!C14*$E23))*'Business Case'!$B$7-'Business Case'!$B$8*(('Business Case'!C11*$C23*'Business Case'!C12*$B23)-('Business Case'!B11*$C23*'Business Case'!B12*$B23))-'Business Case'!C15*$F23 -> 0 | J23: =(('Business Case'!D11*$C23*'Business Case'!D12*$B23)-'Business Case'!D11*$C23*'Business Case'!D13*$D23-'Business Case'!D14*$E23)-MAX(0,(('Business Case'!D11*$C23*'Business Case'!D12*$B23)-'Business Case'!D11*$C23*'Business Case'!D13*$D23-'Business Case'!D14*$E23))*'Business Case'!$B$7-'Business Case'!$B$8*(('Business Case'!D11*$C23*'Business Case'!D12*$B23)-('Business Case'!C11*$C23*'Business Case'!C12*$B23))-'Business Case'!D15*$F23 -> 0 | K23: =(('Business Case'!E11*$C23*'Business Case'!E12*$B23)-'Business Case'!E11*$C23*'Business Case'!E13*$D23-'Business Case'!E14*$E23)-MAX(0,(('Business Case'!E11*$C23*'Business Case'!E12*$B23)-'Business Case'!E11*$C23*'Business Case'!E13*$D23-'Business Case'!E14*$E23))*'Business Case'!$B$7-'Business Case'!$B$8*(('Business Case'!E11*$C23*'Business Case'!E12*$B23)-('Business Case'!D11*$C23*'Business Case'!D12*$B23))-'Business Case'!E15*$F23 -> 0 | L23: =(('Business Case'!F11*$C23*'Business Case'!F12*$B23)-'Business Case'!F11*$C23*'Business Case'!F13*$D23-'Business Case'!F14*$E23)-MAX(0,(('Business Case'!F11*$C23*'Business Case'!F12*$B23)-'Business Case'!F11*$C23*'Business Case'!F13*$D23-'Business Case'!F14*$E23))*'Business Case'!$B$7-'Business Case'!$B$8*(('Business Case'!F11*$C23*'Business Case'!F12*$B23)-('Business Case'!E11*$C23*'Business Case'!E12*$B23))-'Business Case'!F15*$F23 -> 0 | M23: =(('Business Case'!G11*$C23*'Business Case'!G12*$B23)-'Business Case'!G11*$C23*'Business Case'!G13*$D23-'Business Case'!G14*$E23)-MAX(0,(('Business Case'!G11*$C23*'Business Case'!G12*$B23)-'Business Case'!G11*$C23*'Business Case'!G13*$D23-'Business Case'!G14*$E23))*'Business Case'!$B$7-'Business Case'!$B$8*(('Business Case'!G11*$C23*'Business Case'!G12*$B23)-('Business Case'!F11*$C23*'Business Case'!F12*$B23))-'Business Case'!G15*$F23+'Business Case'!$B$8*('Business Case'!G11*$C23*'Business Case'!G12*$B23) -> 0 | N23: =IF(COUNT('Business Case'!B11:G11)=0,"",H23+NPV(G23,I23:M23))
A24: Fixed costs high | B24: =1 -> 1 | C24: =1 -> 1 | D24: =1 -> 1 | E24: =1+G9 -> 1 | F24: =1 -> 1 | G24: ='Business Case'!$B$6 -> 0 | H24: =(('Business Case'!B11*$C24*'Business Case'!B12*$B24)-'Business Case'!B11*$C24*'Business Case'!B13*$D24-'Business Case'!B14*$E24)-MAX(0,(('Business Case'!B11*$C24*'Business Case'!B12*$B24)-'Business Case'!B11*$C24*'Business Case'!B13*$D24-'Business Case'!B14*$E24))*'Business Case'!$B$7-'Business Case'!$B$8*('Business Case'!B11*$C24*'Business Case'!B12*$B24)-'Business Case'!B15*$F24 -> 0 | I24: =(('Business Case'!C11*$C24*'Business Case'!C12*$B24)-'Business Case'!C11*$C24*'Business Case'!C13*$D24-'Business Case'!C14*$E24)-MAX(0,(('Business Case'!C11*$C24*'Business Case'!C12*$B24)-'Business Case'!C11*$C24*'Business Case'!C13*$D24-'Business Case'!C14*$E24))*'Business Case'!$B$7-'Business Case'!$B$8*(('Business Case'!C11*$C24*'Business Case'!C12*$B24)-('Business Case'!B11*$C24*'Business Case'!B12*$B24))-'Business Case'!C15*$F24 -> 0 | J24: =(('Business Case'!D11*$C24*'Business Case'!D12*$B24)-'Business Case'!D11*$C24*'Business Case'!D13*$D24-'Business Case'!D14*$E24)-MAX(0,(('Business Case'!D11*$C24*'Business Case'!D12*$B24)-'Business Case'!D11*$C24*'Business Case'!D13*$D24-'Business Case'!D14*$E24))*'Business Case'!$B$7-'Business Case'!$B$8*(('Business Case'!D11*$C24*'Business Case'!D12*$B24)-('Business Case'!C11*$C24*'Business Case'!C12*$B24))-'Business Case'!D15*$F24 -> 0 | K24: =(('Business Case'!E11*$C24*'Business Case'!E12*$B24)-'Business Case'!E11*$C24*'Business Case'!E13*$D24-'Business Case'!E14*$E24)-MAX(0,(('Business Case'!E11*$C24*'Business Case'!E12*$B24)-'Business Case'!E11*$C24*'Business Case'!E13*$D24-'Business Case'!E14*$E24))*'Business Case'!$B$7-'Business Case'!$B$8*(('Business Case'!E11*$C24*'Business Case'!E12*$B24)-('Business Case'!D11*$C24*'Business Case'!D12*$B24))-'Business Case'!E15*$F24 -> 0 | L24: =(('Business Case'!F11*$C24*'Business Case'!F12*$B24)-'Business Case'!F11*$C24*'Business Case'!F13*$D24-'Business Case'!F14*$E24)-MAX(0,(('Business Case'!F11*$C24*'Business Case'!F12*$B24)-'Business Case'!F11*$C24*'Business Case'!F13*$D24-'Business Case'!F14*$E24))*'Business Case'!$B$7-'Business Case'!$B$8*(('Business Case'!F11*$C24*'Business Case'!F12*$B24)-('Business Case'!E11*$C24*'Business Case'!E12*$B24))-'Business Case'!F15*$F24 -> 0 | M24: =(('Business Case'!G11*$C24*'Business Case'!G12*$B24)-'Business Case'!G11*$C24*'Business Case'!G13*$D24-'Business Case'!G14*$E24)-MAX(0,(('Business Case'!G11*$C24*'Business Case'!G12*$B24)-'Business Case'!G11*$C24*'Business Case'!G13*$D24-'Business Case'!G14*$E24))*'Business Case'!$B$7-'Business Case'!$B$8*(('Business Case'!G11*$C24*'Business Case'!G12*$B24)-('Business Case'!F11*$C24*'Business Case'!F12*$B24))-'Business Case'!G15*$F24+'Business Case'!$B$8*('Business Case'!G11*$C24*'Business Case'!G12*$B24) -> 0 | N24: =IF(COUNT('Business Case'!B11:G11)=0,"",H24+NPV(G24,I24:M24))
A25: Capex low | B25: =1 -> 1 | C25: =1 -> 1 | D25: =1 -> 1 | E25: =1 -> 1 | F25: =1+E10 -> 1 | G25: ='Business Case'!$B$6 -> 0 | H25: =(('Business Case'!B11*$C25*'Business Case'!B12*$B25)-'Business Case'!B11*$C25*'Business Case'!B13*$D25-'Business Case'!B14*$E25)-MAX(0,(('Business Case'!B11*$C25*'Business Case'!B12*$B25)-'Business Case'!B11*$C25*'Business Case'!B13*$D25-'Business Case'!B14*$E25))*'Business Case'!$B$7-'Business Case'!$B$8*('Business Case'!B11*$C25*'Business Case'!B12*$B25)-'Business Case'!B15*$F25 -> 0 | I25: =(('Business Case'!C11*$C25*'Business Case'!C12*$B25)-'Business Case'!C11*$C25*'Business Case'!C13*$D25-'Business Case'!C14*$E25)-MAX(0,(('Business Case'!C11*$C25*'Business Case'!C12*$B25)-'Business Case'!C11*$C25*'Business Case'!C13*$D25-'Business Case'!C14*$E25))*'Business Case'!$B$7-'Business Case'!$B$8*(('Business Case'!C11*$C25*'Business Case'!C12*$B25)-('Business Case'!B11*$C25*'Business Case'!B12*$B25))-'Business Case'!C15*$F25 -> 0 | J25: =(('Business Case'!D11*$C25*'Business Case'!D12*$B25)-'Business Case'!D11*$C25*'Business Case'!D13*$D25-'Business Case'!D14*$E25)-MAX(0,(('Business Case'!D11*$C25*'Business Case'!D12*$B25)-'Business Case'!D11*$C25*'Business Case'!D13*$D25-'Business Case'!D14*$E25))*'Business Case'!$B$7-'Business Case'!$B$8*(('Business Case'!D11*$C25*'Business Case'!D12*$B25)-('Business Case'!C11*$C25*'Business Case'!C12*$B25))-'Business Case'!D15*$F25 -> 0 | K25: =(('Business Case'!E11*$C25*'Business Case'!E12*$B25)-'Business Case'!E11*$C25*'Business Case'!E13*$D25-'Business Case'!E14*$E25)-MAX(0,(('Business Case'!E11*$C25*'Business Case'!E12*$B25)-'Business Case'!E11*$C25*'Business Case'!E13*$D25-'Business Case'!E14*$E25))*'Business Case'!$B$7-'Business Case'!$B$8*(('Business Case'!E11*$C25*'Business Case'!E12*$B25)-('Business Case'!D11*$C25*'Business Case'!D12*$B25))-'Business Case'!E15*$F25 -> 0 | L25: =(('Business Case'!F11*$C25*'Business Case'!F12*$B25)-'Business Case'!F11*$C25*'Business Case'!F13*$D25-'Business Case'!F14*$E25)-MAX(0,(('Business Case'!F11*$C25*'Business Case'!F12*$B25)-'Business Case'!F11*$C25*'Business Case'!F13*$D25-'Business Case'!F14*$E25))*'Business Case'!$B$7-'Business Case'!$B$8*(('Business Case'!F11*$C25*'Business Case'!F12*$B25)-('Business Case'!E11*$C25*'Business Case'!E12*$B25))-'Business Case'!F15*$F25 -> 0 | M25: =(('Business Case'!G11*$C25*'Business Case'!G12*$B25)-'Business Case'!G11*$C25*'Business Case'!G13*$D25-'Business Case'!G14*$E25)-MAX(0,(('Business Case'!G11*$C25*'Business Case'!G12*$B25)-'Business Case'!G11*$C25*'Business Case'!G13*$D25-'Business Case'!G14*$E25))*'Business Case'!$B$7-'Business Case'!$B$8*(('Business Case'!G11*$C25*'Business Case'!G12*$B25)-('Business Case'!F11*$C25*'Business Case'!F12*$B25))-'Business Case'!G15*$F25+'Business Case'!$B$8*('Business Case'!G11*$C25*'Business Case'!G12*$B25) -> 0 | N25: =IF(COUNT('Business Case'!B11:G11)=0,"",H25+NPV(G25,I25:M25))
A26: Capex high | B26: =1 -> 1 | C26: =1 -> 1 | D26: =1 -> 1 | E26: =1 -> 1 | F26: =1+G10 -> 1 | G26: ='Business Case'!$B$6 -> 0 | H26: =(('Business Case'!B11*$C26*'Business Case'!B12*$B26)-'Business Case'!B11*$C26*'Business Case'!B13*$D26-'Business Case'!B14*$E26)-MAX(0,(('Business Case'!B11*$C26*'Business Case'!B12*$B26)-'Business Case'!B11*$C26*'Business Case'!B13*$D26-'Business Case'!B14*$E26))*'Business Case'!$B$7-'Business Case'!$B$8*('Business Case'!B11*$C26*'Business Case'!B12*$B26)-'Business Case'!B15*$F26 -> 0 | I26: =(('Business Case'!C11*$C26*'Business Case'!C12*$B26)-'Business Case'!C11*$C26*'Business Case'!C13*$D26-'Business Case'!C14*$E26)-MAX(0,(('Business Case'!C11*$C26*'Business Case'!C12*$B26)-'Business Case'!C11*$C26*'Business Case'!C13*$D26-'Business Case'!C14*$E26))*'Business Case'!$B$7-'Business Case'!$B$8*(('Business Case'!C11*$C26*'Business Case'!C12*$B26)-('Business Case'!B11*$C26*'Business Case'!B12*$B26))-'Business Case'!C15*$F26 -> 0 | J26: =(('Business Case'!D11*$C26*'Business Case'!D12*$B26)-'Business Case'!D11*$C26*'Business Case'!D13*$D26-'Business Case'!D14*$E26)-MAX(0,(('Business Case'!D11*$C26*'Business Case'!D12*$B26)-'Business Case'!D11*$C26*'Business Case'!D13*$D26-'Business Case'!D14*$E26))*'Business Case'!$B$7-'Business Case'!$B$8*(('Business Case'!D11*$C26*'Business Case'!D12*$B26)-('Business Case'!C11*$C26*'Business Case'!C12*$B26))-'Business Case'!D15*$F26 -> 0 | K26: =(('Business Case'!E11*$C26*'Business Case'!E12*$B26)-'Business Case'!E11*$C26*'Business Case'!E13*$D26-'Business Case'!E14*$E26)-MAX(0,(('Business Case'!E11*$C26*'Business Case'!E12*$B26)-'Business Case'!E11*$C26*'Business Case'!E13*$D26-'Business Case'!E14*$E26))*'Business Case'!$B$7-'Business Case'!$B$8*(('Business Case'!E11*$C26*'Business Case'!E12*$B26)-('Business Case'!D11*$C26*'Business Case'!D12*$B26))-'Business Case'!E15*$F26 -> 0 | L26: =(('Business Case'!F11*$C26*'Business Case'!F12*$B26)-'Business Case'!F11*$C26*'Business Case'!F13*$D26-'Business Case'!F14*$E26)-MAX(0,(('Business Case'!F11*$C26*'Business Case'!F12*$B26)-'Business Case'!F11*$C26*'Business Case'!F13*$D26-'Business Case'!F14*$E26))*'Business Case'!$B$7-'Business Case'!$B$8*(('Business Case'!F11*$C26*'Business Case'!F12*$B26)-('Business Case'!E11*$C26*'Business Case'!E12*$B26))-'Business Case'!F15*$F26 -> 0 | M26: =(('Business Case'!G11*$C26*'Business Case'!G12*$B26)-'Business Case'!G11*$C26*'Business Case'!G13*$D26-'Business Case'!G14*$E26)-MAX(0,(('Business Case'!G11*$C26*'Business Case'!G12*$B26)-'Business Case'!G11*$C26*'Business Case'!G13*$D26-'Business Case'!G14*$E26))*'Business Case'!$B$7-'Business Case'!$B$8*(('Business Case'!G11*$C26*'Business Case'!G12*$B26)-('Business Case'!F11*$C26*'Business Case'!F12*$B26))-'Business Case'!G15*$F26+'Business Case'!$B$8*('Business Case'!G11*$C26*'Business Case'!G12*$B26) -> 0 | N26: =IF(COUNT('Business Case'!B11:G11)=0,"",H26+NPV(G26,I26:M26))
