Workbook

Sheet Start
B2: Strat-IQ Workbook
B3: Global electric vehicles (passenger BEV and PHEV) · base company BYD
B4: Pre-filled from the Strat-IQ ledger (global-ev-demo-2026, as of 2026-10-01).
B6: How to use | C6: Each sheet is one Strat-IQ step, in process order. Type only in the cream cells (blue text). Grey cells are formulas: they score, rank and flag automatically. Every finding should name its evidence, the same rule Strat-IQ follows.
B7: Colour key | C7: Blue on cream = input · black on grey = formula · green / amber / red = status.
B8: Management Interviews | C8: Start here. What management told you: the decisions they need made, the goals you must reach, the questions they need answered, nine questions every team answers, your own questions, and the takeaways you hold yourselves to.
B9: PART 1 · THE INDUSTRY
B10: Industry Overview | C10: Setup (scope, competitors, base company) and the industry introduction: market size side by side, a CAGR calculator, segments, top-4 share and HHI, history, life-cycle stage.
B11: Competitive Analysis | C11: Each competitor's financials and moat against the peer median, margin rank, moat score, signals, and annual-report seeds for PESTEL.
B12: PESTEL | C12: Macro findings with impact × certainty priority and the P&L line each one hits.
B13: Five Forces | C13: Sub-factor scores roll up to each force and to an industry attractiveness score.
B14: Trending Factors | C14: Candidate drivers through the four tests; Driver or Demoted, and a 3-5 driver check.
B15: KSF Scorecard | C15: Weighted KSFs, every competitor scored, totals and rank; weights must sum to 100%.
B16: Strategic Mapping | C16: Every company scored on two vectors, plotted on a map, and the white-space candidates with ERRC and a capability stamp.
B17: PART 2 · THE COMPANY
B18: Value Chain | C18: Activities by cost share and value share; value minus cost reads as differentiating engine, in balance or value trap.
B19: Unit Economics | C19: Contribution, break-even, margin of safety, LTV, LTV/CAC, CAC payback and a sensitivity table (J-1).
B20: Resources & Capabilities | C20: Resources, capabilities (threshold or distinctive) and core competencies.
B21: VRIO | C21: Yes / No / ? for each test; the verdict and the KSF reality check are calculated.
B22: Full Potential | C22: The profit gap to benchmark, driver by driver in sequence, with a bridge chart (K-1).
B23: Growth Barriers | C23: Six barriers marked binding, tight or slack; the binding constraint is named (K-2).
B24: SWOT-TOWS | C24: Four traced lists and the TOWS options that pair them.
B25: PART 3 · THE STRATEGY
B26: Positioning | C26: The strategy you chose, in your words, and five fit tests including management fit.
B27: Strategic Options | C27: SCQ framing and three or more options plus do nothing, each staged with a gate (P).
B28: Decision Matrix | C28: Criteria weights × option scores, with a weighted total and rank; do nothing included.
B29: Business Case | C29: Driver-based cash flows, NPV, IRR and cumulative cash (Q-1).
B30: Expected Value | C30: Scenario probabilities × NPVs, expected NPV, worst case, maximin, value of information, and a Bayes' rule pilot check (Q-2).
B31: Risk Analysis | C31: A tornado chart and a 1,000-run Monte Carlo simulation over your low / likely / high ranges (Q-3).
B32: Pricing | C32: Optional: price points against expected volume; the profit-maximising price inside the acceptable range.
B33: Stress Test | C33: Assumption audit with headroom, competitor war-game, and a risk register with owners and triggers (R).
B34: Go-to-Market | C34: Beachhead, ICP, a channel funnel worked back to CAC, CAC checked against LTV, launch phases (T).
B35: Initiatives | C35: RICE scores and rank; every initiative traces to a finding (S).
B36: Operating Model | C36: Decision rights (RAPID) and a stakeholder power-interest map.
B37: Execution Roadmap | C37: First 100 days as bars by week, milestones and stage gates (S).
... B39: Strategy Map | C39: Objectives by perspective and their cause-and-effect links (U).
B40: GLO-BUS
B41: GLO-BUS CIR | C41: Paste the CIR figures; each company is placed in a strategic group automatically.
B42: GLO-BUS Planner | C42: Plan every decision for each year in screen order; flags big changes and years where price and advertising are both cut. You enter the decisions in GLO-BUS yourself.
B43: Season by Year | C43: All years on one tab: every decision entered (top) and every result (below), each year followed by its change (▲ ▼, green = better). The first columns stay put as you scroll.
...

Sheet Management Interviews
A1: Management Interviews
A2: What management told you, in their words. It sets up everything after it: the memo's Key Issues and Exhibit B, the decision criteria, the strategy you choose, and the weekly check.
A3: Pre-filled from your Strat-IQ ledger. Blue text on cream = inputs you can change. Black on grey = formulas (do not type over them).
A5: 1. Key issues from the interview (these become your memo's Key Issues and Exhibit B)
A6: Central problem: the decision management needs made | C6: How should Company C position cameras and drones to beat investor expectations every year while protecting its credit rating?
A8: # | B8: Decisions management needs us to make | D8: By when | E8: Notes
A9: D1 | B9: Choose a competitive strategy for cameras and for drones | D9: Before Year 6
A10: D2 | B10: Set the yearly price, quality and marketing plan | D10: Every round
A11: D3
A12: D4
A13: D5
A15: # | B15: Required goals (the decision criteria come from these) | D15: Measure / KPI | E15: Target | F15: By when
A16: B1 | B16: Beat investor expectations for EPS | D16: EPS | F16: Every year
A17: B2 | B17: Hold a credit rating of BB or better | D17: Credit rating | E17: BB | F17: Every year
A18: B3 | B18: Keep the image rating at or above expectations | D18: Image rating | F18: From Year 7
A19: B4
A20: B5
A22: # | B22: Questions management needs answered | D22: Why it matters to them
A23: Q1 | B23: Can we grow drone share without hurting the credit rating? | D23: Debt worries the board
A24: Q2
A25: Q3
A26: Q4
A27: Q5
A29: 2. Questions every team must answer
A30: # | B30: Area | C30: Question | D30: What management said | E30: Their words (quote) | F30: What it means for our strategy | G30: Touches | H30: How sure | I30: Follow-up question
A31: M1 | B31: Goals | C31: Which scored measures matter most to management: EPS, ROE, stock price, credit rating or image rating? | D31: EPS first, then the credit rating | E31: We will not take on debt that risks our rating. | F31: Growth funded mostly from earnings | G31: Credit rating | H31: Stated
A32: M2 | B32: Goals | C32: What would management call a successful season, and what would be a failure?
A33: M3 | B33: Strategy | C33: What strategy does management favour for cameras, and for drones? Why? | D33: Value for money in cameras; premium in drones | F33: Best-cost cameras, differentiated drones | G33: Whole strategy | H33: Implied
A34: M4 | B34: Markets | C34: Are there regions or segments management wants to lead in, or to avoid?
A35: M5 | B35: Risk | C35: How much risk will management accept: debt, issuing stock, dividends, the lowest credit rating it will tolerate? | D35: No new debt beyond current levels | F35: Little room for big capacity bets | G35: Finance | H35: Stated
A36: M6 | B36: Brand | C36: Are there minimum quality, warranty, image or CSR standards the company must keep?
A37: M7 | B37: Operations | C37: What are management's views on capacity, workforce and pay?
A38: M8 | B38: Rivals | C38: What does management expect competitors to do?
A39: M9 | B39: Decision rights | C39: Which decisions must the team check with management before entering them?
A41: 3. Our own questions (anything else the team asked)
A42: # | B42: Area | C42: Question | D42: What management said | E42: Their words (quote) | F42: What it means for our strategy | G42: Touches | H42: How sure | I42: Follow-up question
A43: T1 | B43: Markets | C43: Is Latin America worth defending? | D43: Only if it pays its way | H43: Stated
A44: T2
A45: T3
A46: T4
...

Sheet Industry Overview
A1: Setup and Industry Overview
A2: Part 1, steps 1-2. The scope every later step uses, and the business-plan-style introduction to the industry. Cite a source for every figure.
A3: Pre-filled from your Strat-IQ ledger. Blue text on cream = inputs you can change. Black on grey = formulas (do not type over them).
A5: Scope (from setup)
A6: Industry | B6: Global electric vehicles (passenger BEV and PHEV)
A7: In scope / out of scope | B7: Passenger BEV + PHEV cars; excludes two-wheelers, buses and trucks
A8: Geography | B8: Global, with the EU as the decision market
A9: Horizon | B9: 2026-2030
A10: Competitor set | B10: BYD, Tesla, Volkswagen Group, Geely, Xiaomi, Stellantis
A11: Base company | B11: BYD
A13: Market size (estimates differ by definition: show them side by side)
A14: Value | B14: Unit | C14: Year | D14: Publisher | E14: Definition | F14: Matches scope?
A15: 21 | B15: million units | C15: 2026 | D15: Demo source A | E15: BEV + PHEV passenger cars | F15: Yes
A16: 14 | B16: million units | C16: 2026 | D16: Demo source B | E16: BEV only | F16: No
A21: Growth: compound annual growth rate calculator
A22: Start value
A23: End value
A24: Number of years
A25: CAGR | B25: =IFERROR((B23/B22)^(1/B24)-1,"")
A27: Forecast: publisher | B27: CAGR | C27: To year | D27: Published
A28: Demo source A | B28: 0.14 | C28: 2030 | D28: 2026
A29: Demo source C | B29: 0.11 | C29: 2030 | D29: 2026
A33: Segments and customers
A34: Segment | B34: Share | C34: Growth | D34: Who buys, and why
A35: Compact / city | B35: 0.34 | C35: fast | D35: Urban households; price first
A36: Mid-size SUV | B36: 0.38 | C36: steady | D36: Families; range and space
A37: Premium | B37: 0.18 | C37: slowing | D37: Tech-first buyers; software and brand
A38: Fleet | B38: 0.1 | C38: fast | D38: Companies; total cost of ownership
A41: Key players and concentration
A42: Company | B42: Market share
A43: BYD | B43: 0.22 | D43: Top-4 share | E43: =IF(COUNT(B43:B50)<4,"",LARGE(B43:B50,1)+LARGE(B43:B50,2)+LARGE(B43:B50,3)+LARGE(B43:B50,4)) -> 0.48
A44: Tesla | B44: 0.11 | D44: HHI (shares listed) | E44: =IF(COUNT(B43:B50)=0,"",SUMPRODUCT(B43:B50*100,B43:B50*100)) -> 738
A45: Geely | B45: 0.08 | D45: Below 1,500 unconcentrated; above 2,500 highly concentrated.
A46: Volkswagen Group | B46: 0.07
A47: Stellantis | B47: 0.04
A48: Xiaomi | B48: 0.02
A52: Recent history: the events that explain today's structure
A53: Year | B53: Event | C53: Why it mattered
A54: 2020 | B54: LFP cells return to mainstream cars | C54: Cut pack cost and opened the budget segment
A55: 2023 | B55: China price war begins | C55: Margins compressed; scale became decisive
...

Sheet Competitive Analysis
A1: Competitive Analysis
A2: Part 1, step 3. Each competitor's financials, moat and signals, benchmarked against the peer median. Same fiscal year for all; note the currency.
A3: Pre-filled from your Strat-IQ ledger. Blue text on cream = inputs you can change. Black on grey = formulas (do not type over them).
A5: Financial benchmark and moat
A6: Company | B6: Fiscal year | C6: Currency | D6: Revenue (m) | E6: Gross margin | F6: Op. margin | G6: R&D % rev. | H6: Moat: network | I6: Moat: switching | J6: Moat: scale | K6: Moat: intangibles | L6: Apparent strategy
A7: BYD | B7: FY2025 | C7: USD | D7: 107000 | E7: 0.2 | F7: 0.06 | G7: 0.07 | H7: weak | I7: moderate | J7: strong | K7: moderate | L7: Cost leader at scale; vertical integration
A8: Tesla | B8: FY2025 | C8: USD | D8: 97000 | E8: 0.18 | F8: 0.07 | G8: 0.05 | H8: moderate | I8: moderate | J8: strong | K8: strong | L8: Premium tech brand; software and charging
A9: Volkswagen Group | B9: FY2025 | C9: USD | D9: 350000 | E9: 0.18 | F9: 0.06 | G9: 0.06 | H9: weak | I9: moderate | J9: strong | K9: strong | L9: Broad multi-brand; transitioning from ICE
A10: Geely | B10: FY2025 | C10: USD | D10: 33000 | E10: 0.16 | F10: 0.04 | G10: 0.05 | H10: weak | I10: weak | J10: moderate | K10: moderate | L10: Multi-brand value; platform sharing
A11: Xiaomi | B11: FY2025 | C11: USD | D11: 15000 | E11: 0.19 | F11: -0.02 | G11: 0.09 | H11: strong | I11: strong | J11: weak | K11: moderate | L11: Ecosystem differentiator; phone-car link
A12: Stellantis | B12: FY2025 | C12: USD | D12: 170000 | E12: 0.17 | F12: 0.05 | G12: 0.04 | H12: weak | I12: moderate | J12: strong | K12: moderate | L12: Regional brands; cost discipline
A17: Peer median | D17: =IF(COUNT(D7:D16)=0,"",MEDIAN(D7:D16)) -> 102000 | E17: =IF(COUNT(E7:E16)=0,"",MEDIAN(E7:E16)) -> 0.18 | F17: =IF(COUNT(F7:F16)=0,"",MEDIAN(F7:F16)) -> 0.055 | G17: =IF(COUNT(G7:G16)=0,"",MEDIAN(G7:G16)) -> 0.055
A20: Company | B20: Op. margin vs median | C20: Margin rank | D20: Moat score (0-8)
A21: =IF(A7="","",A7) -> BYD | B21: =IF(OR(F7="",$F$17=""),"",F7-$F$17) -> 0.005 | C21: =IF(F7="","",RANK(F7,$F$7:$F$16)) -> 2 | D21: =IF(A7="","",IF(H7="strong",2,IF(H7="moderate",1,0))+IF(I7="strong",2,IF(I7="moderate",1,0))+IF(J7="strong",2,IF(J7="moderate",1,0))+IF(K7="strong",2,IF(K7="moderate",1,0))) -> 4
A22: =IF(A8="","",A8) -> Tesla | B22: =IF(OR(F8="",$F$17=""),"",F8-$F$17) -> 0.015 | C22: =IF(F8="","",RANK(F8,$F$7:$F$16)) -> 1 | D22: =IF(A8="","",IF(H8="strong",2,IF(H8="moderate",1,0))+IF(I8="strong",2,IF(I8="moderate",1,0))+IF(J8="strong",2,IF(J8="moderate",1,0))+IF(K8="strong",2,IF(K8="moderate",1,0))) -> 6
A23: =IF(A9="","",A9) -> Volkswagen Group | B23: =IF(OR(F9="",$F$17=""),"",F9-$F$17) -> 0.005 | C23: =IF(F9="","",RANK(F9,$F$7:$F$16)) -> 2 | D23: =IF(A9="","",IF(H9="strong",2,IF(H9="moderate",1,0))+IF(I9="strong",2,IF(I9="moderate",1,0))+IF(J9="strong",2,IF(J9="moderate",1,0))+IF(K9="strong",2,IF(K9="moderate",1,0))) -> 5
A24: =IF(A10="","",A10) -> Geely | B24: =IF(OR(F10="",$F$17=""),"",F10-$F$17) -> -0.015 | C24: =IF(F10="","",RANK(F10,$F$7:$F$16)) -> 5 | D24: =IF(A10="","",IF(H10="strong",2,IF(H10="moderate",1,0))+IF(I10="strong",2,IF(I10="moderate",1,0))+IF(J10="strong",2,IF(J10="moderate",1,0))+IF(K10="strong",2,IF(K10="moderate",1,0))) -> 2
A25: =IF(A11="","",A11) -> Xiaomi | B25: =IF(OR(F11="",$F$17=""),"",F11-$F$17) -> -0.075 | C25: =IF(F11="","",RANK(F11,$F$7:$F$16)) -> 6 | D25: =IF(A11="","",IF(H11="strong",2,IF(H11="moderate",1,0))+IF(I11="strong",2,IF(I11="moderate",1,0))+IF(J11="strong",2,IF(J11="moderate",1,0))+IF(K11="strong",2,IF(K11="moderate",1,0))) -> 5
A26: =IF(A12="","",A12) -> Stellantis | B26: =IF(OR(F12="",$F$17=""),"",F12-$F$17) -> -0.005 | C26: =IF(F12="","",RANK(F12,$F$7:$F$16)) -> 4 | D26: =IF(A12="","",IF(H12="strong",2,IF(H12="moderate",1,0))+IF(I12="strong",2,IF(I12="moderate",1,0))+IF(J12="strong",2,IF(J12="moderate",1,0))+IF(K12="strong",2,IF(K12="moderate",1,0))) -> 4
A27: =IF(A13="","",A13) | B27: =IF(OR(F13="",$F$17=""),"",F13-$F$17) | C27: =IF(F13="","",RANK(F13,$F$7:$F$16)) | D27: =IF(A13="","",IF(H13="strong",2,IF(H13="moderate",1,0))+IF(I13="strong",2,IF(I13="moderate",1,0))+IF(J13="strong",2,IF(J13="moderate",1,0))+IF(K13="strong",2,IF(K13="moderate",1,0)))
A28: =IF(A14="","",A14) | B28: =IF(OR(F14="",$F$17=""),"",F14-$F$17) | C28: =IF(F14="","",RANK(F14,$F$7:$F$16)) | D28: =IF(A14="","",IF(H14="strong",2,IF(H14="moderate",1,0))+IF(I14="strong",2,IF(I14="moderate",1,0))+IF(J14="strong",2,IF(J14="moderate",1,0))+IF(K14="strong",2,IF(K14="moderate",1,0)))
A29: =IF(A15="","",A15) | B29: =IF(OR(F15="",$F$17=""),"",F15-$F$17) | C29: =IF(F15="","",RANK(F15,$F$7:$F$16)) | D29: =IF(A15="","",IF(H15="strong",2,IF(H15="moderate",1,0))+IF(I15="strong",2,IF(I15="moderate",1,0))+IF(J15="strong",2,IF(J15="moderate",1,0))+IF(K15="strong",2,IF(K15="moderate",1,0)))
A30: =IF(A16="","",A16) | B30: =IF(OR(F16="",$F$17=""),"",F16-$F$17) | C30: =IF(F16="","",RANK(F16,$F$7:$F$16)) | D30: =IF(A16="","",IF(H16="strong",2,IF(H16="moderate",1,0))+IF(I16="strong",2,IF(I16="moderate",1,0))+IF(J16="strong",2,IF(J16="moderate",1,0))+IF(K16="strong",2,IF(K16="moderate",1,0)))
A32: Signals: what competitors are doing (hiring, patents, launches, capex, pricing)
A33: Company | B33: Kind | C33: Observation | H33: What it suggests
A34: BYD | B34: capex | C34: Hungary plant construction on schedule | H34: Local EU production from 2026 to avoid duties
A35: Tesla | B35: pricing | C35: Model Y price cut 5% in Europe | H35: Defending share against cheaper entrants
A36: Volkswagen Group | B36: partnership | C36: Software joint venture with a US EV maker | H36: Buying software depth it lacks
A37: Xiaomi | B37: hiring | C37: Hiring EU homologation engineers | H37: Preparing an EU launch within two years
A45: Annual-report seeds for PESTEL (risk factors and management discussion)
A46: PESTEL | B46: Kind | C46: Text | D46: P&L line | E46: Firms citing it

Sheet PESTEL
A1: PESTEL Analysis
A2: Macro findings, each tied to a P&L line. Priority = impact × certainty (1-25).
A3: Pre-filled from your Strat-IQ ledger. Blue text on cream = inputs you can change. Black on grey = formulas (do not type over them).
A5: ID | B5: Dimension | C5: Finding | D5: Direction (+ / - / ±) | E5: Impact 1-5 | F5: Certainty 1-5 | G5: Priority | H5: P&L line | I5: Source / evidence
A6: P1 | B6: Economic | C6: Battery cell prices keep falling | D6: + | E6: 5 | F6: 3 | G6: =IF(AND(ISNUMBER(E6),ISNUMBER(F6)),E6*F6,"") -> 15 | H6: cogs.inputs | I6: E003
A7: P2 | B7: Political | C7: EU tariffs on China-built BEVs | D7: - | E7: 5 | F7: 5 | G7: =IF(AND(ISNUMBER(E7),ISNUMBER(F7)),E7*F7,"") -> 25 | H7: tax_and_levies | I7: E002
A8: P3 | B8: Technological | C8: Software-defined vehicles shift value to features | D8: + | E8: 5 | F8: 3 | G8: =IF(AND(ISNUMBER(E8),ISNUMBER(F8)),E8*F8,"") -> 15 | H8: revenue.mix | I8: E008
A9: P4 | B9: Social | C9: Range and charging anxiety slow mass-market adoption | D9: - | E9: 3 | F9: 3 | G9: =IF(AND(ISNUMBER(E9),ISNUMBER(F9)),E9*F9,"") -> 9 | H9: revenue.volume | I9: E007
A10: P5 | B10: Env | C10: Fleet CO2 targets push OEMs to sell more BEVs | D10: + | E10: 3 | F10: 5 | G10: =IF(AND(ISNUMBER(E10),ISNUMBER(F10)),E10*F10,"") -> 15 | H10: revenue.volume | I10: E005
A11: P6 | B11: Legal | C11: Local-content rules for EU incentives | D11: - | E11: 3 | F11: 3 | G11: =IF(AND(ISNUMBER(E11),ISNUMBER(F11)),E11*F11,"") -> 9 | H11: revenue.price | I11: E002
G12: =IF(AND(ISNUMBER(E12),ISNUMBER(F12)),E12*F12,"")
G13: =IF(AND(ISNUMBER(E13),ISNUMBER(F13)),E13*F13,"")
G14: =IF(AND(ISNUMBER(E14),ISNUMBER(F14)),E14*F14,"")
G15: =IF(AND(ISNUMBER(E15),ISNUMBER(F15)),E15*F15,"")
G16: =IF(AND(ISNUMBER(E16),ISNUMBER(F16)),E16*F16,"")
G17: =IF(AND(ISNUMBER(E17),ISNUMBER(F17)),E17*F17,"")
G18: =IF(AND(ISNUMBER(E18),ISNUMBER(F18)),E18*F18,"")
G19: =IF(AND(ISNUMBER(E19),ISNUMBER(F19)),E19*F19,"")
G20: =IF(AND(ISNUMBER(E20),ISNUMBER(F20)),E20*F20,"")
G21: =IF(AND(ISNUMBER(E21),ISNUMBER(F21)),E21*F21,"")
G22: =IF(AND(ISNUMBER(E22),ISNUMBER(F22)),E22*F22,"")
G23: =IF(AND(ISNUMBER(E23),ISNUMBER(F23)),E23*F23,"")
... G30: =IF(AND(ISNUMBER(E30),ISNUMBER(F30)),E30*F30,"")
B32: Findings | C32: =COUNTA(C6:C30) -> 6
B33: High priority (≥16) | C33: =COUNTIF(G6:G30,">=16") -> 1
B34: Missing a source | C34: =SUMPRODUCT((C6:C30<>"")*(I6:I30="")) -> 0

Sheet Five Forces
A1: Porter's Five Forces
A2: Score each sub-factor 1 (weak force, good for profit) to 5 (strong force). A force score you enter overrides the sub-factor average.
A3: Pre-filled from your Strat-IQ ledger. Blue text on cream = inputs you can change. Black on grey = formulas (do not type over them).
A5: Force | B5: Sub-factor | C5: Score 1-5 | D5: Evidence / source
A6: Competitive rivalry | B6: Current competition
A7: Competitive rivalry | B7: Market growth
A8: Competitive rivalry | B8: Exit barriers
A9: Competitive rivalry | B9: Differentiation
A10: Supplier power | B10: Supplier concentration
A11: Supplier power | B11: Switching costs
A12: Supplier power | B12: Forward integration
A13: Supplier power | B13: Input uniqueness
A14: Buyer power | B14: Buyer concentration
A15: Buyer power | B15: Purchase volume
A16: Buyer power | B16: Switching costs
A17: Buyer power | B17: Price sensitivity
... A25: Threat of substitutes | B25: Buyer propensity
A27: Force | B27: Sub-factor average | C27: Your force score (optional) | D27: Score used | E27: Strength | F27: Horizon score (optional)
A28: Competitive rivalry | B28: =IFERROR(AVERAGEIF($A$6:$A$25,A28,$C$6:$C$25),"") | C28: 5 | D28: =IF(ISNUMBER(C28),C28,B28) -> 5 | E28: =IF(D28="","",IF(D28>=4,"Strong",IF(D28>=2.5,"Moderate","Weak"))) -> Strong | F28: 5
A29: Supplier power | B29: =IFERROR(AVERAGEIF($A$6:$A$25,A29,$C$6:$C$25),"") | C29: 4 | D29: =IF(ISNUMBER(C29),C29,B29) -> 4 | E29: =IF(D29="","",IF(D29>=4,"Strong",IF(D29>=2.5,"Moderate","Weak"))) -> Strong | F29: 3
A30: Buyer power | B30: =IFERROR(AVERAGEIF($A$6:$A$25,A30,$C$6:$C$25),"") | C30: 3 | D30: =IF(ISNUMBER(C30),C30,B30) -> 3 | E30: =IF(D30="","",IF(D30>=4,"Strong",IF(D30>=2.5,"Moderate","Weak"))) -> Moderate | F30: 4
A31: Threat of new entrants | B31: =IFERROR(AVERAGEIF($A$6:$A$25,A31,$C$6:$C$25),"") | C31: 4 | D31: =IF(ISNUMBER(C31),C31,B31) -> 4 | E31: =IF(D31="","",IF(D31>=4,"Strong",IF(D31>=2.5,"Moderate","Weak"))) -> Strong | F31: 4
A32: Threat of substitutes | B32: =IFERROR(AVERAGEIF($A$6:$A$25,A32,$C$6:$C$25),"") | C32: 2 | D32: =IF(ISNUMBER(C32),C32,B32) -> 2 | E32: =IF(D32="","",IF(D32>=4,"Strong",IF(D32>=2.5,"Moderate","Weak"))) -> Weak | F32: 2
A34: Industry attractiveness (1-5) | B34: =IFERROR(6-AVERAGE(D28:D32),"") -> 2.4
A35: At the horizon | B35: =IF(COUNT(F28:F32)=5,6-AVERAGE(F28:F32),"") -> 2.4
A37: Attractiveness = 6 minus the average force score (1-5; higher is more attractive).
A38: The horizon score appears once all five horizon scores are entered.

Sheet Trending Factors
A1: Trending Influence Factors
A2: Part 1, step 6. Candidates from PESTEL and Competitive Analysis; a driver must pass all four tests. Keep 3-5.
A3: Pre-filled from your Strat-IQ ledger. Blue text on cream = inputs you can change. Black on grey = formulas (do not type over them).
A5: ID | B5: Candidate driver | C5: From (PESTEL / CI ids) | D5: Mechanism → P&L | E5: P&L line | F5: Forces moved | G5: Moves a force ≥1 pt? | H5: Moves P&L for most firms? | I5: Acts within horizon? | J5: Two source types? | K5: Verdict | L5: Profit pool
A6: D1 | B6: Cell cost curve | C6: P1 | D6: Cheaper cells → lower input cost → lower price points | E6: cogs.inputs | F6: suppliers, entrants | G6: Yes | H6: Yes | I6: Yes | J6: Yes | K6: =IF(B6="","",IF(COUNTIF(G6:J6,"Yes")=4,"Driver","Demoted")) -> Driver | L6: redistributing
A7: D2 | B7: Trade barriers | C7: P2, P6 | E7: revenue.volume | G7: Yes | H7: Yes | I7: Yes | J7: Yes | K7: =IF(B7="","",IF(COUNTIF(G7:J7,"Yes")=4,"Driver","Demoted")) -> Driver | L7: redistributing
A8: D3 | B8: Software value shift | C8: P3 | E8: revenue.volume | G8: Yes | H8: Yes | I8: Yes | J8: Yes | K8: =IF(B8="","",IF(COUNTIF(G8:J8,"Yes")=4,"Driver","Demoted")) -> Driver | L8: redistributing
K9: =IF(B9="","",IF(COUNTIF(G9:J9,"Yes")=4,"Driver","Demoted"))
K10: =IF(B10="","",IF(COUNTIF(G10:J10,"Yes")=4,"Driver","Demoted"))
K11: =IF(B11="","",IF(COUNTIF(G11:J11,"Yes")=4,"Driver","Demoted"))
K12: =IF(B12="","",IF(COUNTIF(G12:J12,"Yes")=4,"Driver","Demoted"))
K13: =IF(B13="","",IF(COUNTIF(G13:J13,"Yes")=4,"Driver","Demoted"))
K14: =IF(B14="","",IF(COUNTIF(G14:J14,"Yes")=4,"Driver","Demoted"))
K15: =IF(B15="","",IF(COUNTIF(G15:J15,"Yes")=4,"Driver","Demoted"))
K16: =IF(B16="","",IF(COUNTIF(G16:J16,"Yes")=4,"Driver","Demoted"))
K17: =IF(B17="","",IF(COUNTIF(G17:J17,"Yes")=4,"Driver","Demoted"))
A19: Drivers kept | C19: =COUNTIF(K6:K17,"Driver")&" of "&COUNTA(B6:B17)&" candidates" -> 3 of 3 candidates | D19: =IF(COUNTA(B6:B17)=0,"",IF(AND(COUNTIF(K6:K17,"Driver")>=3,COUNTIF(K6:K17,"Driver")<=5),"OK: 3-5 drivers","Aim for 3-5 drivers")) -> OK: 3-5 drivers

Sheet KSF Scorecard
A1: Key Success Factors Scorecard
A2: Weights are fractions that must sum to 100%. Score each competitor 1 (weak) to 5 (strong) on each KSF.
A3: Pre-filled from your Strat-IQ ledger. Blue text on cream = inputs you can change. Black on grey = formulas (do not type over them).
A5: ID | B5: Key success factor | C5: Weight | D5: Traces to (force / driver) | E5: BYD | F5: Tesla | G5: Volkswagen Group | H5: Geely | I5: Xiaomi | J5: Stellantis
A6: K1 | B6: Battery cost and supply | C6: 0.3 | D6: suppliers, D1 | E6: 5 | F6: 4 | G6: 3 | H6: 4 | I6: 3 | J6: 2
A7: K2 | B7: Software and UX | C7: 0.25 | D7: rivalry, D3 | E7: 3 | F7: 5 | G7: 2 | H7: 3 | I7: 5 | J7: 2
A8: K3 | B8: Local production footprint | C8: 0.2 | D8: D2 | E8: 2 | F8: 4 | G8: 5 | H8: 3 | I8: 1 | J8: 5
A9: K4 | B9: Brand trust in Europe | C9: 0.15 | D9: buyers | E9: 2 | F9: 3 | G9: 5 | H9: 3 | I9: 2 | J9: 4
A10: K5 | B10: Charging and service network | C10: 0.1 | D10: D3 | E10: 3 | F10: 5 | G10: 4 | H10: 3 | I10: 2 | J10: 3
B16: Weight check (must be 100%) | C16: =SUM(C6:C15) -> 1 | D16: =IF(ABS(C16-1)<0.001,"OK","Weights must sum to 100%") -> OK
B17: Weighted score (out of 5) | E17: =IF(COUNT(E6:E15)=0,"",SUMPRODUCT($C$6:$C$15,E6:E15)) -> 3.25 | F17: =IF(COUNT(F6:F15)=0,"",SUMPRODUCT($C$6:$C$15,F6:F15)) -> 4.2 | G17: =IF(COUNT(G6:G15)=0,"",SUMPRODUCT($C$6:$C$15,G6:G15)) -> 3.55 | H17: =IF(COUNT(H6:H15)=0,"",SUMPRODUCT($C$6:$C$15,H6:H15)) -> 3.3 | I17: =IF(COUNT(I6:I15)=0,"",SUMPRODUCT($C$6:$C$15,I6:I15)) -> 2.85 | J17: =IF(COUNT(J6:J15)=0,"",SUMPRODUCT($C$6:$C$15,J6:J15)) -> 3
B18: Rank | E18: =IF(E17="","",RANK(E17,$E$17:$J$17)) -> 4 | F18: =IF(F17="","",RANK(F17,$E$17:$J$17)) -> 1 | G18: =IF(G17="","",RANK(G17,$E$17:$J$17)) -> 2 | H18: =IF(H17="","",RANK(H17,$E$17:$J$17)) -> 3 | I18: =IF(I17="","",RANK(I17,$E$17:$J$17)) -> 6 | J18: =IF(J17="","",RANK(J17,$E$17:$J$17)) -> 5

Sheet Strategic Mapping
A1: Strategic Mapping
A2: Part 1, step 8. Score each company on two vectors (0-10), see the map, then list the white space and stamp each candidate after VRIO.
A3: Pre-filled from your Strat-IQ ledger. Blue text on cream = inputs you can change. Black on grey = formulas (do not type over them).
A5: Horizontal axis (vector) | B5: Price position (low → high)
A6: Vertical axis (vector) | B6: Software depth (low → high)
A8: Company | B8: X score (0-10) | C8: Y score (0-10) | D8: Size (share or revenue)
A9: BYD | B9: 3 | C9: 5 | D9: 22
A10: Tesla | B10: 7 | C10: 9 | D10: 11
A11: Volkswagen Group | B11: 6 | C11: 4 | D11: 7
A12: Geely | B12: 4 | C12: 5 | D12: 8
A13: Xiaomi | B13: 5 | C13: 9 | D13: 2
A14: Stellantis | B14: 5 | C14: 3 | D14: 4
A30: White space and blue-ocean candidates
A31: Rank | B31: X | C31: Y | D31: Demand | E31: Thesis | F31: Eliminate | G31: Reduce | H31: Raise | I31: Create | J31: Capability (after VRIO)
A32: 1 | B32: 3 | C32: 7 | D32: evidence of demand | E32: Sub-EUR 25k EU compact with good software | F32: Dealer upsell | G32: Trim levels | H32: Software UX | I32: Battery-backed resale guarantee | J32: supported
A33: 2 | B33: 8 | C33: 9 | D33: unpriced | E33: Premium software subscription layer | G33: Hardware variety | H33: App ecosystem | I33: Paid feature store | J33: gap

Sheet Value Chain
A1: Value Chain
A2: Part 2, step 9. Each activity's share of cost and of the value customers pay for. Value minus cost shows where the firm earns its margin.
A3: Pre-filled from your Strat-IQ ledger. Blue text on cream = inputs you can change. Black on grey = formulas (do not type over them).
A5: ID | B5: Activity | C5: Porter category | D5: Stage | E5: Sourcing | F5: Cost share | G5: Value share | H5: Value − cost | I5: Reading | J5: Delivers KSF
A6: A1 | B6: Battery cells and packs | C6: Operations | D6: product | E6: in-house | F6: 0.35 | G6: 0.3 | H6: =IF(OR(F6="",G6=""),"",G6-F6) -> -0.05 | I6: =IF(B6="","",IF(H6="","No figures",IF(H6>0.05,"Differentiating engine",IF(H6<-0.05,"Value trap","In balance")))) -> In balance | J6: K1
A7: A2 | B7: Vehicle assembly | C7: Operations | D7: commodity | E7: in-house | F7: 0.25 | G7: 0.15 | H7: =IF(OR(F7="",G7=""),"",G7-F7) -> -0.1 | I7: =IF(B7="","",IF(H7="","No figures",IF(H7>0.05,"Differentiating engine",IF(H7<-0.05,"Value trap","In balance")))) -> Value trap | J7: K3
A8: A3 | B8: Software and connected services | C8: Technology | D8: custom | E8: mixed | F8: 0.08 | G8: 0.18 | H8: =IF(OR(F8="",G8=""),"",G8-F8) -> 0.1 | I8: =IF(B8="","",IF(H8="","No figures",IF(H8>0.05,"Differentiating engine",IF(H8<-0.05,"Value trap","In balance")))) -> Differentiating engine | J8: K2
A9: A4 | B9: Design and engineering | C9: Technology | D9: product | E9: in-house | F9: 0.1 | G9: 0.12 | H9: =IF(OR(F9="",G9=""),"",G9-F9) -> 0.02 | I9: =IF(B9="","",IF(H9="","No figures",IF(H9>0.05,"Differentiating engine",IF(H9<-0.05,"Value trap","In balance")))) -> In balance | J9: K2, K5
A10: A5 | B10: Logistics and import | C10: Outbound logistics | D10: commodity | E10: outsourced | F10: 0.07 | G10: 0.03 | H10: =IF(OR(F10="",G10=""),"",G10-F10) -> -0.04 | I10: =IF(B10="","",IF(H10="","No figures",IF(H10>0.05,"Differentiating engine",IF(H10<-0.05,"Value trap","In balance")))) -> In balance
A11: A6 | B11: EU sales and dealer network | C11: Marketing and sales | D11: product | E11: mixed | F11: 0.1 | G11: 0.14 | H11: =IF(OR(F11="",G11=""),"",G11-F11) -> 0.04 | I11: =IF(B11="","",IF(H11="","No figures",IF(H11>0.05,"Differentiating engine",IF(H11<-0.05,"Value trap","In balance")))) -> In balance | J11: K4
A12: A7 | B12: After-sales service | C12: Service | D12: product | E12: outsourced | F12: 0.05 | G12: 0.08 | H12: =IF(OR(F12="",G12=""),"",G12-F12) -> 0.03 | I12: =IF(B12="","",IF(H12="","No figures",IF(H12>0.05,"Differentiating engine",IF(H12<-0.05,"Value trap","In balance")))) -> In balance | J12: K4
H13: =IF(OR(F13="",G13=""),"",G13-F13) | I13: =IF(B13="","",IF(H13="","No figures",IF(H13>0.05,"Differentiating engine",IF(H13<-0.05,"Value trap","In balance"))))
H14: =IF(OR(F14="",G14=""),"",G14-F14) | I14: =IF(B14="","",IF(H14="","No figures",IF(H14>0.05,"Differentiating engine",IF(H14<-0.05,"Value trap","In balance"))))
H15: =IF(OR(F15="",G15=""),"",G15-F15) | I15: =IF(B15="","",IF(H15="","No figures",IF(H15>0.05,"Differentiating engine",IF(H15<-0.05,"Value trap","In balance"))))
H16: =IF(OR(F16="",G16=""),"",G16-F16) | I16: =IF(B16="","",IF(H16="","No figures",IF(H16>0.05,"Differentiating engine",IF(H16<-0.05,"Value trap","In balance"))))
H17: =IF(OR(F17="",G17=""),"",G17-F17) | I17: =IF(B17="","",IF(H17="","No figures",IF(H17>0.05,"Differentiating engine",IF(H17<-0.05,"Value trap","In balance"))))
A18: Totals | F18: =SUM(F6:F17) -> 1 | G18: =SUM(G6:G17) -> 1 | H18: =IF(AND(ABS(F18-1)<0.02,ABS(G18-1)<0.02),"Both sum to 100%","Cost and value shares should each sum to 100%") -> Both sum to 100%

Sheet Unit Economics
A1: Unit Economics (Exhibit J-1)
A2: Part 2, step 10. Does one more unit make money, and what does a customer cost? Matches unit_economics.py.
A3: Pre-filled from your Strat-IQ ledger. Blue text on cream = inputs you can change. Black on grey = formulas (do not type over them).
A5: Inputs | D5: Results
A6: Unit | B6: one compact car (EU) | D6: Contribution per unit | E6: =IF(OR(B7="",B8=""),"",B7-B8) -> 12000 | H6: 0 | I6: =IFERROR(IF($E$12-H6<=0,0,$E$11*MIN(1,$E$12-H6)/(1+B14)^H6),0) -> 2700
A7: Price per unit | B7: 32000 | D7: Contribution margin | E7: =IFERROR(E6/B7,"") -> 0.375 | H7: 1 | I7: =IFERROR(IF($E$12-H7<=0,0,$E$11*MIN(1,$E$12-H7)/(1+B14)^H7),0) -> 2454.5455
A8: Variable cost per unit | B8: 20000 | D8: Break-even volume | E8: =IFERROR(IF(E6>0,B9/E6,"never"),"") -> 15000 | H8: 2 | I8: =IFERROR(IF($E$12-H8<=0,0,$E$11*MIN(1,$E$12-H8)/(1+B14)^H8),0) -> 1115.7025
A9: Fixed costs per period | B9: 180000000 | D9: Margin of safety | E9: =IFERROR((B10-E8)/B10,"") -> 0.53703704 | H9: 3 | I9: =IFERROR(IF($E$12-H9<=0,0,$E$11*MIN(1,$E$12-H9)/(1+B14)^H9),0) -> 0
A10: Volume per period | B10: 32400 | D10: Operating profit | E10: =IFERROR(E6*B10-B9,"") -> 208800000 | H10: 4 | I10: =IFERROR(IF($E$12-H10<=0,0,$E$11*MIN(1,$E$12-H10)/(1+B14)^H10),0) -> 0
A11: Customer acquisition cost (CAC) | B11: 1500 | D11: Annual contribution per customer | E11: =IFERROR(E6*B12+N(B15),"") -> 2700 | H11: 5 | I11: =IFERROR(IF($E$12-H11<=0,0,$E$11*MIN(1,$E$12-H11)/(1+B14)^H11),0) -> 0
A12: Units per customer per year | B12: 0.2 | D12: Customer lifetime (years, max 10) | E12: =IFERROR(IF(B13>=1,10,MIN(10,1/(1-B13))),"") -> 2.5 | H12: 6 | I12: =IFERROR(IF($E$12-H12<=0,0,$E$11*MIN(1,$E$12-H12)/(1+B14)^H12),0) -> 0
A13: Retention (share kept each year) | B13: 0.6 | D13: Lifetime value (LTV) | E13: =IF(E11="","",SUM(I6:I15)) -> 6270.2479 | H13: 7 | I13: =IFERROR(IF($E$12-H13<=0,0,$E$11*MIN(1,$E$12-H13)/(1+B14)^H13),0) -> 0
A14: Discount rate | B14: 0.1 | D14: LTV / CAC | E14: =IFERROR(E13/B11,"") -> 4.1801653 | H14: 8 | I14: =IFERROR(IF($E$12-H14<=0,0,$E$11*MIN(1,$E$12-H14)/(1+B14)^H14),0) -> 0
A15: Service margin per customer per year | B15: 300 | D15: CAC payback (months) | E15: =IFERROR(B11/(E11/12),"") -> 6.6666667 | H15: 9 | I15: =IFERROR(IF($E$12-H15<=0,0,$E$11*MIN(1,$E$12-H15)/(1+B14)^H15),0) -> 0
A18: Sensitivity: operating profit when one input moves
A19: Input | B19: −10% | C19: Plan | D19: +10%
A20: Price | B20: =IFERROR(((B7*(1+-0.1))-B8)*B10-B9,"") -> 105120000 | C20: =IFERROR(((B7*(1+0))-B8)*B10-B9,"") -> 208800000 | D20: =IFERROR(((B7*(1+0.1))-B8)*B10-B9,"") -> 312480000
A21: Variable cost | B21: =IFERROR((B7-B8*(1+-0.1))*B10-B9,"") -> 273600000 | C21: =IFERROR((B7-B8*(1+0))*B10-B9,"") -> 208800000 | D21: =IFERROR((B7-B8*(1+0.1))*B10-B9,"") -> 144000000
A22: Volume | B22: =IFERROR((B7-B8)*B10*(1+-0.1)-B9,"") -> 169920000 | C22: =IFERROR((B7-B8)*B10*(1+0)-B9,"") -> 208800000 | D22: =IFERROR((B7-B8)*B10*(1+0.1)-B9,"") -> 247680000
A23: Fixed costs | B23: =IFERROR((B7-B8)*B10-B9*(1+-0.1),"") -> 226800000 | C23: =IFERROR((B7-B8)*B10-B9*(1+0),"") -> 208800000 | D23: =IFERROR((B7-B8)*B10-B9*(1+0.1),"") -> 190800000

Sheet Resources & Capabilities
A1: Resources and Capabilities
A2: Part 2, step 11. What the firm owns, what it does well, and which capabilities might be core competencies (VRIO tests them next).
A3: Pre-filled from your Strat-IQ ledger. Blue text on cream = inputs you can change. Black on grey = formulas (do not type over them).
A5: Resources
A6: ID | B6: Resource | C6: Type | D6: Measure or evidence
A7: R1 | B7: In-house cell and pack plants | C7: tangible | D7: Over 200 GWh of cell capacity
A8: R2 | B8: Scale in China | C8: tangible | D8: Largest unit volume in China
A9: R3 | B9: Blade-cell patents | C9: intangible | D9: Patent family in LFP pack design
A10: R4 | B10: EU plant site (Hungary) | C10: tangible | D10: Under construction
A16: Capabilities
A17: ID | B17: Capability | C17: Combines (resources) | D17: Performance evidence | E17: From activity | F17: Class
A18: C1 | B18: Vertical battery integration | C18: R1, R3 | D18: Cell cost per kWh below peers | E18: A1 | F18: distinctive
A19: C2 | B19: Fast model cadence | C19: R2 | D19: New model every 12-18 months | E19: A4 | F19: distinctive
A20: C3 | B20: In-car software and OTA | D20: OTA updates; app rated below leaders | E20: A3 | F20: threshold
A27: Core competencies (Prahalad and Hamel: customer benefit, hard to imitate, extendable)
A28: Capability | B28: Customer benefit (KSF) | C28: Hard to imitate because | D28: Extends to | E28: Status
A29: C1 Vertical battery integration | B29: K1: lower price at equal range | C29: Decades of cell know-how plus owned capacity | D29: Storage, buses, licensing | E29: confirmed
A30: C2 Fast model cadence | B30: K5: fresh models | C30: Partly: rivals are speeding up | D30: New segments | E30: candidate
A35: Counts | B35: =COUNTA(B7:B14)&" resources · "&COUNTA(B18:B25)&" capabilities ("&COUNTIF(F18:F25,"distinctive")&" distinctive) · "&COUNTIF(E29:E33,"confirmed")&" confirmed core competencies" -> 4 resources · 3 capabilities (2 distinctive) · 1 confirmed core competencies

Sheet VRIO
A1: VRIO Analysis
A2: Answer the four tests in order with Yes / No / ?. The verdict stops at the first No or ?. KSF weight (a fraction) drives the reality check.
A3: Pre-filled from your Strat-IQ ledger. Blue text on cream = inputs you can change. Black on grey = formulas (do not type over them).
A5: Resource or capability | B5: Type | C5: Valuable? | D5: Rare? | E5: Inimitable? | F5: Organized? | G5: Verdict | H5: KSF it delivers | I5: KSF weight | J5: Reality check | K5: Evidence
A6: Vertical battery integration | B6: capability | C6: Yes | D6: Yes | E6: Yes | F6: Yes | G6: =IF(A6="","",IF(C6<>"Yes",IF(C6="No","Competitive disadvantage","Undetermined"),IF(D6<>"Yes",IF(D6="No","Competitive parity","Undetermined beyond valuable"),IF(E6<>"Yes",IF(E6="No","Temporary advantage","Undetermined beyond rare"),IF(F6="Yes","Sustained advantage",IF(F6="No","Unexploited advantage","Undetermined beyond inimitable")))))) -> Sustained advantage | H6: K1 | I6: 0.3 | J6: =IF(A6="","",IF(AND(C6="Yes",D6="Yes",E6="Yes",N(I6)<0.1),"Competence trap",IF(AND(OR(G6="Temporary advantage",G6="Unexploited advantage",G6="Sustained advantage"),N(I6)>=0.1),"Supported",IF(AND(G6="Competitive parity",N(I6)>=0.1),"Table stakes","")))) -> Supported | K6: E010
A7: Fast model cadence | B7: capability | C7: Yes | D7: Yes | E7: No | F7: Yes | G7: =IF(A7="","",IF(C7<>"Yes",IF(C7="No","Competitive disadvantage","Undetermined"),IF(D7<>"Yes",IF(D7="No","Competitive parity","Undetermined beyond valuable"),IF(E7<>"Yes",IF(E7="No","Temporary advantage","Undetermined beyond rare"),IF(F7="Yes","Sustained advantage",IF(F7="No","Unexploited advantage","Undetermined beyond inimitable")))))) -> Temporary advantage | H7: K2 | I7: 0.25 | J7: =IF(A7="","",IF(AND(C7="Yes",D7="Yes",E7="Yes",N(I7)<0.1),"Competence trap",IF(AND(OR(G7="Temporary advantage",G7="Unexploited advantage",G7="Sustained advantage"),N(I7)>=0.1),"Supported",IF(AND(G7="Competitive parity",N(I7)>=0.1),"Table stakes","")))) -> Supported | K7: E001
A8: In-car software and OTA | B8: capability | C8: Yes | D8: No | E8: No | F8: ? | G8: =IF(A8="","",IF(C8<>"Yes",IF(C8="No","Competitive disadvantage","Undetermined"),IF(D8<>"Yes",IF(D8="No","Competitive parity","Undetermined beyond valuable"),IF(E8<>"Yes",IF(E8="No","Temporary advantage","Undetermined beyond rare"),IF(F8="Yes","Sustained advantage",IF(F8="No","Unexploited advantage","Undetermined beyond inimitable")))))) -> Competitive parity | H8: K2 | I8: 0.25 | J8: =IF(A8="","",IF(AND(C8="Yes",D8="Yes",E8="Yes",N(I8)<0.1),"Competence trap",IF(AND(OR(G8="Temporary advantage",G8="Unexploited advantage",G8="Sustained advantage"),N(I8)>=0.1),"Supported",IF(AND(G8="Competitive parity",N(I8)>=0.1),"Table stakes","")))) -> Table stakes | K8: E008
A9: Scale in China | B9: resource | C9: Yes | D9: Yes | E9: ? | F9: Yes | G9: =IF(A9="","",IF(C9<>"Yes",IF(C9="No","Competitive disadvantage","Undetermined"),IF(D9<>"Yes",IF(D9="No","Competitive parity","Undetermined beyond valuable"),IF(E9<>"Yes",IF(E9="No","Temporary advantage","Undetermined beyond rare"),IF(F9="Yes","Sustained advantage",IF(F9="No","Unexploited advantage","Undetermined beyond inimitable")))))) -> Undetermined beyond rare | H9: K1 | I9: 0.3 | J9: =IF(A9="","",IF(AND(C9="Yes",D9="Yes",E9="Yes",N(I9)<0.1),"Competence trap",IF(AND(OR(G9="Temporary advantage",G9="Unexploited advantage",G9="Sustained advantage"),N(I9)>=0.1),"Supported",IF(AND(G9="Competitive parity",N(I9)>=0.1),"Table stakes","")))) | K9: E001
G10: =IF(A10="","",IF(C10<>"Yes",IF(C10="No","Competitive disadvantage","Undetermined"),IF(D10<>"Yes",IF(D10="No","Competitive parity","Undetermined beyond valuable"),IF(E10<>"Yes",IF(E10="No","Temporary advantage","Undetermined beyond rare"),IF(F10="Yes","Sustained advantage",IF(F10="No","Unexploited advantage","Undetermined beyond inimitable")))))) | J10: =IF(A10="","",IF(AND(C10="Yes",D10="Yes",E10="Yes",N(I10)<0.1),"Competence trap",IF(AND(OR(G10="Temporary advantage",G10="Unexploited advantage",G10="Sustained advantage"),N(I10)>=0.1),"Supported",IF(AND(G10="Competitive parity",N(I10)>=0.1),"Table stakes",""))))
G11: =IF(A11="","",IF(C11<>"Yes",IF(C11="No","Competitive disadvantage","Undetermined"),IF(D11<>"Yes",IF(D11="No","Competitive parity","Undetermined beyond valuable"),IF(E11<>"Yes",IF(E11="No","Temporary advantage","Undetermined beyond rare"),IF(F11="Yes","Sustained advantage",IF(F11="No","Unexploited advantage","Undetermined beyond inimitable")))))) | J11: =IF(A11="","",IF(AND(C11="Yes",D11="Yes",E11="Yes",N(I11)<0.1),"Competence trap",IF(AND(OR(G11="Temporary advantage",G11="Unexploited advantage",G11="Sustained advantage"),N(I11)>=0.1),"Supported",IF(AND(G11="Competitive parity",N(I11)>=0.1),"Table stakes",""))))
G12: =IF(A12="","",IF(C12<>"Yes",IF(C12="No","Competitive disadvantage","Undetermined"),IF(D12<>"Yes",IF(D12="No","Competitive parity","Undetermined beyond valuable"),IF(E12<>"Yes",IF(E12="No","Temporary advantage","Undetermined beyond rare"),IF(F12="Yes","Sustained advantage",IF(F12="No","Unexploited advantage","Undetermined beyond inimitable")))))) | J12: =IF(A12="","",IF(AND(C12="Yes",D12="Yes",E12="Yes",N(I12)<0.1),"Competence trap",IF(AND(OR(G12="Temporary advantage",G12="Unexploited advantage",G12="Sustained advantage"),N(I12)>=0.1),"Supported",IF(AND(G12="Competitive parity",N(I12)>=0.1),"Table stakes",""))))
G13: =IF(A13="","",IF(C13<>"Yes",IF(C13="No","Competitive disadvantage","Undetermined"),IF(D13<>"Yes",IF(D13="No","Competitive parity","Undetermined beyond valuable"),IF(E13<>"Yes",IF(E13="No","Temporary advantage","Undetermined beyond rare"),IF(F13="Yes","Sustained advantage",IF(F13="No","Unexploited advantage","Undetermined beyond inimitable")))))) | J13: =IF(A13="","",IF(AND(C13="Yes",D13="Yes",E13="Yes",N(I13)<0.1),"Competence trap",IF(AND(OR(G13="Temporary advantage",G13="Unexploited advantage",G13="Sustained advantage"),N(I13)>=0.1),"Supported",IF(AND(G13="Competitive parity",N(I13)>=0.1),"Table stakes",""))))
G14: =IF(A14="","",IF(C14<>"Yes",IF(C14="No","Competitive disadvantage","Undetermined"),IF(D14<>"Yes",IF(D14="No","Competitive parity","Undetermined beyond valuable"),IF(E14<>"Yes",IF(E14="No","Temporary advantage","Undetermined beyond rare"),IF(F14="Yes","Sustained advantage",IF(F14="No","Unexploited advantage","Undetermined beyond inimitable")))))) | J14: =IF(A14="","",IF(AND(C14="Yes",D14="Yes",E14="Yes",N(I14)<0.1),"Competence trap",IF(AND(OR(G14="Temporary advantage",G14="Unexploited advantage",G14="Sustained advantage"),N(I14)>=0.1),"Supported",IF(AND(G14="Competitive parity",N(I14)>=0.1),"Table stakes",""))))
G15: =IF(A15="","",IF(C15<>"Yes",IF(C15="No","Competitive disadvantage","Undetermined"),IF(D15<>"Yes",IF(D15="No","Competitive parity","Undetermined beyond valuable"),IF(E15<>"Yes",IF(E15="No","Temporary advantage","Undetermined beyond rare"),IF(F15="Yes","Sustained advantage",IF(F15="No","Unexploited advantage","Undetermined beyond inimitable")))))) | J15: =IF(A15="","",IF(AND(C15="Yes",D15="Yes",E15="Yes",N(I15)<0.1),"Competence trap",IF(AND(OR(G15="Temporary advantage",G15="Unexploited advantage",G15="Sustained advantage"),N(I15)>=0.1),"Supported",IF(AND(G15="Competitive parity",N(I15)>=0.1),"Table stakes",""))))
G16: =IF(A16="","",IF(C16<>"Yes",IF(C16="No","Competitive disadvantage","Undetermined"),IF(D16<>"Yes",IF(D16="No","Competitive parity","Undetermined beyond valuable"),IF(E16<>"Yes",IF(E16="No","Temporary advantage","Undetermined beyond rare"),IF(F16="Yes","Sustained advantage",IF(F16="No","Unexploited advantage","Undetermined beyond inimitable")))))) | J16: =IF(A16="","",IF(AND(C16="Yes",D16="Yes",E16="Yes",N(I16)<0.1),"Competence trap",IF(AND(OR(G16="Temporary advantage",G16="Unexploited advantage",G16="Sustained advantage"),N(I16)>=0.1),"Supported",IF(AND(G16="Competitive parity",N(I16)>=0.1),"Table stakes",""))))
G17: =IF(A17="","",IF(C17<>"Yes",IF(C17="No","Competitive disadvantage","Undetermined"),IF(D17<>"Yes",IF(D17="No","Competitive parity","Undetermined beyond valuable"),IF(E17<>"Yes",IF(E17="No","Temporary advantage","Undetermined beyond rare"),IF(F17="Yes","Sustained advantage",IF(F17="No","Unexploited advantage","Undetermined beyond inimitable")))))) | J17: =IF(A17="","",IF(AND(C17="Yes",D17="Yes",E17="Yes",N(I17)<0.1),"Competence trap",IF(AND(OR(G17="Temporary advantage",G17="Unexploited advantage",G17="Sustained advantage"),N(I17)>=0.1),"Supported",IF(AND(G17="Competitive parity",N(I17)>=0.1),"Table stakes",""))))
G18: =IF(A18="","",IF(C18<>"Yes",IF(C18="No","Competitive disadvantage","Undetermined"),IF(D18<>"Yes",IF(D18="No","Competitive parity","Undetermined beyond valuable"),IF(E18<>"Yes",IF(E18="No","Temporary advantage","Undetermined beyond rare"),IF(F18="Yes","Sustained advantage",IF(F18="No","Unexploited advantage","Undetermined beyond inimitable")))))) | J18: =IF(A18="","",IF(AND(C18="Yes",D18="Yes",E18="Yes",N(I18)<0.1),"Competence trap",IF(AND(OR(G18="Temporary advantage",G18="Unexploited advantage",G18="Sustained advantage"),N(I18)>=0.1),"Supported",IF(AND(G18="Competitive parity",N(I18)>=0.1),"Table stakes",""))))
G19: =IF(A19="","",IF(C19<>"Yes",IF(C19="No","Competitive disadvantage","Undetermined"),IF(D19<>"Yes",IF(D19="No","Competitive parity","Undetermined beyond valuable"),IF(E19<>"Yes",IF(E19="No","Temporary advantage","Undetermined beyond rare"),IF(F19="Yes","Sustained advantage",IF(F19="No","Unexploited advantage","Undetermined beyond inimitable")))))) | J19: =IF(A19="","",IF(AND(C19="Yes",D19="Yes",E19="Yes",N(I19)<0.1),"Competence trap",IF(AND(OR(G19="Temporary advantage",G19="Unexploited advantage",G19="Sustained advantage"),N(I19)>=0.1),"Supported",IF(AND(G19="Competitive parity",N(I19)>=0.1),"Table stakes",""))))
G20: =IF(A20="","",IF(C20<>"Yes",IF(C20="No","Competitive disadvantage","Undetermined"),IF(D20<>"Yes",IF(D20="No","Competitive parity","Undetermined beyond valuable"),IF(E20<>"Yes",IF(E20="No","Temporary advantage","Undetermined beyond rare"),IF(F20="Yes","Sustained advantage",IF(F20="No","Unexploited advantage","Undetermined beyond inimitable")))))) | J20: =IF(A20="","",IF(AND(C20="Yes",D20="Yes",E20="Yes",N(I20)<0.1),"Competence trap",IF(AND(OR(G20="Temporary advantage",G20="Unexploited advantage",G20="Sustained advantage"),N(I20)>=0.1),"Supported",IF(AND(G20="Competitive parity",N(I20)>=0.1),"Table stakes",""))))

Sheet Full Potential
A1: Full Potential (Exhibit K-1)
A2: Part 2, step 14. The profit gap to a benchmark, driver by driver, applied in sequence so overlaps count once. A ceiling, not a forecast. Matches full_potential.py.
A3: Pre-filled from your Strat-IQ ledger. Blue text on cream = inputs you can change. Black on grey = formulas (do not type over them).
A5: Driver | B5: Today | C5: Benchmark | D5: Benchmark source | E5: Controllability | F5: Value after step | G5: Gap captured
A6: Price per unit | B6: 30000 | C6: 32000 | D6: EU peer median | E6: capability-bound | F6: =IF(B6="","",IF(C6="",B6,MAX(B6,C6))) -> 32000 | G6: =IFERROR(((F6+N(B7)-B9)*B8-B10)-((B6+N(B7)-B9)*B8-B10),"") -> 600000000
A7: Mix premium per unit | B7: 0 | C7: 800 | D7: Tesla software attach | E7: capability-bound | F7: =IF(B7="","",IF(C7="",B7,MAX(B7,C7))) -> 800 | G7: =IFERROR(((F6+N(F7)-B9)*B8-B10)-((F6+N(B7)-B9)*B8-B10),"") -> 240000000
A8: Volume | B8: 300000 | C8: 360000 | D8: Plant design capacity | E8: controllable | F8: =IF(B8="","",IF(C8="",B8,MAX(B8,C8))) -> 360000 | G8: =IFERROR(((F6+N(F7)-B9)*F8-B10)-((F6+N(F7)-B9)*B8-B10),"") -> 528000000
A9: Variable cost per unit | B9: 24000 | C9: 22500 | D9: China cost with local cells | E9: controllable | F9: =IF(B9="","",IF(C9="",B9,MIN(B9,C9))) -> 22500 | G9: =IFERROR(((F6+N(F7)-F9)*F8-B10)-((F6+N(F7)-B9)*F8-B10),"") -> 540000000
A10: Fixed costs | B10: 1800000000 | C10: 1700000000 | D10: Peer median | E10: structural | F10: =IF(B10="","",IF(C10="",B10,MIN(B10,C10))) -> 1700000000 | G10: =IFERROR(((F6+N(F7)-F9)*F8-F10)-((F6+N(F7)-F9)*F8-B10),"") -> 100000000
A12: Operating profit today | B12: =IFERROR(((B6+N(B7)-B9)*B8-B10),"") -> 0
A13: Full-potential operating profit | B13: =IFERROR(((F6+N(F7)-F9)*F8-F10),"") -> 2008000000
A14: Uplift | B14: =IFERROR(B13-B12,"") -> 2008000000 | C14: =IFERROR(B14/ABS(B12),"")
A15: Largest gap | B15: =IFERROR(INDEX(A6:A10,MATCH(MAX(G6:G10),G6:G10,0)),"") -> Price per unit

Sheet Growth Barriers
A1: Growth Barriers (Exhibit K-2)
A2: Part 2, step 15. Which constraint binds growth now? Exactly one should be binding; lifting it is what unlocks the next stage.
A3: Pre-filled from your Strat-IQ ledger. Blue text on cream = inputs you can change. Black on grey = formulas (do not type over them).
A5: Barrier | B5: Status | C5: Evidence | D5: What lifting it unlocks
A6: Demand: enough customers want it | B6: slack | C6: Compact segment growing fastest
A7: Supply / capacity | B7: slack | C7: Cell capacity ample
A8: Capability / talent | B8: tight | C8: Software lags leaders (C3)
A9: Capital / funding | B9: slack | C9: Strong cash generation
A10: Distribution / market access | B10: binding | C10: Few dealers in Germany and France | D10: Dealer coverage in DE/FR unlocks the volume the plant needs
A11: Regulation / licences | B11: tight | C11: EU duties on China-built BEVs
A13: Binding constraint | B13: =IF(COUNTIF(B6:B11,"binding")=1,INDEX(A6:A11,MATCH("binding",B6:B11,0)),IF(COUNTIF(B6:B11,"binding")=0,"None marked","More than one: choose the one that binds first")) -> Distribution / market access

Sheet SWOT-TOWS
A1: SWOT and TOWS
A2: Every item names the finding it came from. TOWS options pair the items by ID.
A3: Pre-filled from your Strat-IQ ledger. Blue text on cream = inputs you can change. Black on grey = formulas (do not type over them).
A5: ID | B5: Strengths (internal, helpful) | C5: Source | E5: ID | F5: Weaknesses (internal, harmful) | G5: Source
A6: S1 | B6: Lowest cell cost in the industry | C6: C1 | E6: W1 | F6: Low brand trust in Europe | G6: K4
A7: S2 | B7: Fast model cadence | C7: C2 | E7: W2 | F7: Software lags the leaders | G7: C3
A8: S3 | E8: W3
A9: S4 | E9: W4
A10: S5 | E10: W5
A11: S6 | E11: W6
A14: ID | B14: Opportunities (external, helpful) | C14: Source | E14: ID | F14: Threats (external, harmful) | G14: Source
A15: O1 | B15: Affordable EU compact segment is under-served | C15: W1 | E15: T1 | F15: EU tariffs on China-built BEVs | G15: P2
A16: O2 | B16: Fleet CO2 targets lift BEV demand | C16: P5 | E16: T2 | F16: Local-content rules for incentives | G16: P6
A17: O3 | E17: T3
A18: O4 | E18: T4
A19: O5 | E19: T5
A20: O6 | E20: T6
A23: Cell | B23: TOWS strategic option | C23: Pairs (e.g. S1 × O1)
A24: ST | B24: Build an EU plant to avoid tariffs | C24: S1 × T1
A25: SO | B25: Launch a sub-EUR 25k compact | C25: S1 × O1
A26: WT | B26: Partner with a European OEM for local assembly and brand | C26: W1 × T2

Sheet Positioning
A1: Positioning (Strategy Interview)
A2: Part 3, step 17. The strategy you chose, in your words, and the four fit tests. The workbook records; it never chooses.
A3: Pre-filled from your Strat-IQ ledger. Blue text on cream = inputs you can change. Black on grey = formulas (do not type over them).
A5: Generic strategy | B5: Best-cost provider
A6: Target customers | B6: Price-conscious EU urban buyers and small fleets
A7: Source of advantage | B7: Battery cost lead (C1) funds good-enough software at a lower price
A8: Why now | B8: Duties push local production; compact segment is under-served
A9: What we will not do | B9: Chase premium software subscriptions
A10: Positioning statement (your words) | B10: For price-conscious European city buyers, BYD offers a compact EV with dependable software for under EUR 25k, because our battery cost lead lets us price below rivals without losing money. [team's words]
A12: Fit test | B12: Question | C12: Verdict | D12: Evidence
A13: Market fit | B13: Is there demand where you are aiming (maps, segments, trends)? | C13: supported | D13: Segments: compact growing fastest
A14: Competitive fit | B14: Can you hold the position against the rivals near it? | C14: open question | D14: Tesla price cuts; Xiaomi entering
A15: Capability fit | B15: Do VRIO and the capability stamps support it? | C15: supported | D15: VRIO: C1 sustained
A16: Economic fit | B16: Do unit economics and the business case work? | C16: open question | D16: Option A NPV −$34.5M at plan
A17: Management fit | B17: Does it fit the goals and limits from your management interview? | C17: supported | D17: Goal B1 profit by 2029
A19: Fit summary | B19: =COUNTIF(C13:C17,"supported")&" supported · "&COUNTIF(C13:C17,"open question")&" open · "&COUNTIF(C13:C17,"conflicts")&" conflicts" -> 3 supported · 2 open · 0 conflicts

Sheet Strategic Options
A1: Strategic Options (Exhibit P)
A2: Part 3, step 18. Frame the decision, then three or more distinct options plus do nothing, each with a staged first step and a gate.
A3: Pre-filled from your Strat-IQ ledger. Blue text on cream = inputs you can change. Black on grey = formulas (do not type over them).
A5: Situation | B5: BYD leads global EV volume on cost, but is small in Europe.
A6: Complication | B6: EU duties on China-built cars and weak dealer access cap European growth.
A7: Question | B7: How should BYD build a profitable European position by 2029?
A9: ID | B9: Option | C9: Route | D9: Exploits (TOWS ids) | E9: Staged first step | F9: Gate to the next stage | G9: Suggested?
A10: O-A | B10: A. EU plant | C10: build | D10: ST1, SO1 | E10: Pilot line in Hungary | F10: Orders > 40k by end of year 1 | G10: No
A11: O-B | B11: B. Partner | C11: partner | D11: WT1 | E11: Assembly MoU with a European OEM | F11: Partner volumes > 30k in year 1 | G11: No
A12: O-0 | B12: 0. Do nothing | C12: do nothing | G12: No
A19: Checks | B19: =IF(COUNTIF(C10:C17,"do nothing")=0,"Add do nothing as the baseline",IF(COUNTA(B10:B17)-1<3,"Add options: aim for three or more plus do nothing","OK")) -> Add options: aim for three or more plus do nothing

Sheet Decision Matrix
A1: Decision Matrix
A2: Weight each criterion 1-5 and score each option 1-5. Include do nothing.
A3: Pre-filled from your Strat-IQ ledger. Blue text on cream = inputs you can change. Black on grey = formulas (do not type over them).
A5: Criterion | B5: Weight 1-5 | C5: Tied to goal | D5: A. EU plant | E5: B. Partner | F5: 0. Do nothing | G5: Option 4 | H5: Option 5
A6: Profit by 2029 | B6: 5 | C6: B1 | D6: 4 | E6: 3 | F6: 1
A7: Avoids tariffs | B7: 4 | C7: B2 | D7: 5 | E7: 4 | F7: 1
A8: Capital at risk (low = good) | B8: 3 | C8: B1 | D8: 1 | E8: 4 | F8: 5
A9: Builds EU brand trust | B9: 3 | C9: B3 | D9: 3 | E9: 5 | F9: 1
A14: Weighted score (out of 5) | D14: =IF(COUNT(D6:D13)=0,"",SUMPRODUCT($B$6:$B$13,D6:D13)/SUMPRODUCT($B$6:$B$13*(D6:D13<>""))) -> 3.4666667 | E14: =IF(COUNT(E6:E13)=0,"",SUMPRODUCT($B$6:$B$13,E6:E13)/SUMPRODUCT($B$6:$B$13*(E6:E13<>""))) -> 3.8666667 | F14: =IF(COUNT(F6:F13)=0,"",SUMPRODUCT($B$6:$B$13,F6:F13)/SUMPRODUCT($B$6:$B$13*(F6:F13<>""))) -> 1.8 | G14: =IF(COUNT(G6:G13)=0,"",SUMPRODUCT($B$6:$B$13,G6:G13)/SUMPRODUCT($B$6:$B$13*(G6:G13<>""))) | H14: =IF(COUNT(H6:H13)=0,"",SUMPRODUCT($B$6:$B$13,H6:H13)/SUMPRODUCT($B$6:$B$13*(H6:H13<>"")))
A15: Rank | D15: =IF(D14="","",RANK(D14,$D$14:$H$14)) -> 2 | E15: =IF(E14="","",RANK(E14,$D$14:$H$14)) -> 1 | F15: =IF(F14="","",RANK(F14,$D$14:$H$14)) -> 3 | G15: =IF(G14="","",RANK(G14,$D$14:$H$14)) | H15: =IF(H14="","",RANK(H14,$D$14:$H$14))
A17: The matrix ranks; it does not choose. The recommendation is yours.

Sheet Business Case
A1: Business Case
A2: One option. Year 0 is the investment year. Working capital is released in the final year. Money in $.
A3: Pre-filled from your Strat-IQ ledger. Blue text on cream = inputs you can change. Black on grey = formulas (do not type over them).
A4: Option: A. EU plant (from the ledger)
A5: Assumptions
A6: Discount rate | B6: 0.1
A7: Tax rate | B7: 0.21
A8: Working capital (% of revenue) | B8: 0.05
A10: $ | B10: Year 0 | C10: Year 1 | D10: Year 2 | E10: Year 3 | F10: Year 4 | G10: Year 5
A11: Units | B11: 0 | C11: 32400 | D11: 64800 | E11: 97200 | F11: 108000 | G11: 108000
A12: Price per unit | B12: 32000 | C12: 32000 | D12: 32000 | E12: 32000 | F12: 32000 | G12: 32000
A13: Variable cost per unit | B13: 20000 | C13: 20000 | D13: 20000 | E13: 20000 | F13: 20000 | G13: 20000
A14: Fixed costs | B14: 0 | C14: 180000000 | D14: 180000000 | E14: 180000000 | F14: 180000000 | G14: 180000000
A15: Capex | B15: 2000000000 | C15: 100000000 | D15: 100000000 | E15: 50000000 | F15: 50000000 | G15: 50000000
A16: Revenue | B16: =B11*B12 -> 0 | C16: =C11*C12 -> 1036800000 | D16: =D11*D12 -> 2073600000 | E16: =E11*E12 -> 3110400000 | F16: =F11*F12 -> 3456000000 | G16: =G11*G12 -> 3456000000
A17: Contribution | B17: =B11*(B12-B13) -> 0 | C17: =C11*(C12-C13) -> 388800000 | D17: =D11*(D12-D13) -> 777600000 | E17: =E11*(E12-E13) -> 1166400000 | F17: =F11*(F12-F13) -> 1296000000 | G17: =G11*(G12-G13) -> 1296000000
A18: Operating profit (EBIT) | B18: =B17-B14 -> 0 | C18: =C17-C14 -> 208800000 | D18: =D17-D14 -> 597600000 | E18: =E17-E14 -> 986400000 | F18: =F17-F14 -> 1116000000 | G18: =G17-G14 -> 1116000000
A19: Tax | B19: =MAX(0,B18)*$B$7 -> 0 | C19: =MAX(0,C18)*$B$7 -> 43848000 | D19: =MAX(0,D18)*$B$7 -> 125496000 | E19: =MAX(0,E18)*$B$7 -> 207144000 | F19: =MAX(0,F18)*$B$7 -> 234360000 | G19: =MAX(0,G18)*$B$7 -> 234360000
A20: Working capital | B20: =B16*$B$8 -> 0 | C20: =C16*$B$8 -> 51840000 | D20: =D16*$B$8 -> 103680000 | E20: =E16*$B$8 -> 155520000 | F20: =F16*$B$8 -> 172800000 | G20: =G16*$B$8 -> 172800000
A21: Change in working capital | B21: =B20 -> 0 | C21: =C20-B20 -> 51840000 | D21: =D20-C20 -> 51840000 | E21: =E20-D20 -> 51840000 | F21: =F20-E20 -> 17280000 | G21: =G20-F20 -> 0
A22: Cash flow | B22: =B18-B19-B21-B15 -> -2000000000 | C22: =C18-C19-C21-C15 -> 13112000 | D22: =D18-D19-D21-D15 -> 320264000 | E22: =E18-E19-E21-E15 -> 677416000 | F22: =F18-F19-F21-F15 -> 814360000 | G22: =G18-G19-G21-G15+G20 -> 1004440000
A23: Cumulative cash flow | B23: =B22 -> -2000000000 | C23: =B23+C22 -> -1986888000 | D23: =C23+D22 -> -1666624000 | E23: =D23+E22 -> -989208000 | F23: =E23+F22 -> -174848000 | G23: =F23+G22 -> 829592000
A25: NPV | B25: =IF(COUNT(B11:G11)=0,"",B22+NPV($B$6,C22:G22)) -> -34549290
A26: IRR | B26: =IFERROR(IRR(B22:G22),"n/a") -> 0.09493193
A27: Clears the hurdle? | B27: =IF(ISNUMBER(B26),IF(B26>=$B$6,"Yes","No"),"") -> No
A29: State the break-even in words in your exhibit (the Business Case skill computes it).

Sheet Expected Value
A1: Expected Value
A2: Probabilities as percentages that sum to 100% per option; NPV in $M. Follows the course handout 'Choosing Among Strategic Alternatives'.
A3: Pre-filled from your Strat-IQ ledger. Blue text on cream = inputs you can change. Black on grey = formulas (do not type over them).
A5: Option | B5: P strong | C5: NPV strong ($M) | D5: P moderate | E5: NPV moderate ($M) | F5: P weak | G5: NPV weak ($M) | H5: Probability check | I5: Expected NPV ($M) | J5: Worst case | K5: Best case
A6: A. EU plant | B6: 0.3 | C6: 620 | D6: 0.5 | E6: -35 | F6: 0.2 | G6: -540 | H6: =IF(A6="","",IF(ABS(B6+D6+F6-1)<0.001,"OK","Must sum to 100%")) -> OK | I6: =IF(A6="","",B6*C6+D6*E6+F6*G6) -> 60.5 | J6: =IF(A6="","",MIN(C6,E6,G6)) -> -540 | K6: =IF(A6="","",MAX(C6,E6,G6)) -> 620
A7: B. Partner | B7: 0.3 | C7: 260 | D7: 0.5 | E7: 40 | F7: 0.2 | G7: -60 | H7: =IF(A7="","",IF(ABS(B7+D7+F7-1)<0.001,"OK","Must sum to 100%")) -> OK | I7: =IF(A7="","",B7*C7+D7*E7+F7*G7) -> 86 | J7: =IF(A7="","",MIN(C7,E7,G7)) -> -60 | K7: =IF(A7="","",MAX(C7,E7,G7)) -> 260
A8: 0. Do nothing | B8: 0.3 | C8: 0 | D8: 0.5 | E8: 0 | F8: 0.2 | G8: 0 | H8: =IF(A8="","",IF(ABS(B8+D8+F8-1)<0.001,"OK","Must sum to 100%")) -> OK | I8: =IF(A8="","",B8*C8+D8*E8+F8*G8) -> 0 | J8: =IF(A8="","",MIN(C8,E8,G8)) -> 0 | K8: =IF(A8="","",MAX(C8,E8,G8)) -> 0
H9: =IF(A9="","",IF(ABS(B9+D9+F9-1)<0.001,"OK","Must sum to 100%")) | I9: =IF(A9="","",B9*C9+D9*E9+F9*G9) | J9: =IF(A9="","",MIN(C9,E9,G9)) | K9: =IF(A9="","",MAX(C9,E9,G9))
H10: =IF(A10="","",IF(ABS(B10+D10+F10-1)<0.001,"OK","Must sum to 100%")) | I10: =IF(A10="","",B10*C10+D10*E10+F10*G10) | J10: =IF(A10="","",MIN(C10,E10,G10)) | K10: =IF(A10="","",MAX(C10,E10,G10))
